Workbook
Name modelNames: Names!$A$1:$B$19

Sheet README
B2: Once you have ran Main_Section_5.m and

Sheet rmsfe
A1: OriginalVariableNames | B1: T_1 | C1: T_2 | D1: T_3 | E1: T_4 | F1: T_5 | G1: T_6 | H1: T_7 | I1: T_8 | J1: varcell | K1: speccell | L1: cuntcell | M1: dataspeccell | N1: modelname
A2: y_DE_N15G3f_spec02 | B2: 1 | C2: 1 | D2: 1 | E2: 1 | F2: 1 | G2: 1 | H2: 1 | I2: 1 | J2: y | K2: spec02 | L2: DE | M2: N15G3f | N2: =VLOOKUP(K2,modelNames,2,FALSE) -> ZS
A3: y_DE_N15G3f_spec01 | B3: 0.98348555 | C3: 1.0152793 | D3: 0.97763966 | E3: 0.946038 | F3: 1.0033709 | G3: 0.99149068 | H3: 0.96123831 | I3: 0.97644871 | J3: y | K3: spec01 | L3: DE | M3: N15G3f | N3: =VLOOKUP(K3,modelNames,2,FALSE) -> ZS\&POOL
A4: y_DE_N15G3f_spec04 | B4: 0.98034768 | C4: 1.0427682 | D4: 0.99952552 | E4: 0.95175094 | F4: 1.0109871 | G4: 0.98720472 | H4: 0.96381849 | I4: 1.0351922 | J4: y | K4: spec04 | L4: DE | M4: N15G3f | N4: =VLOOKUP(K4,modelNames,2,FALSE) -> ZSGL
A5: y_DE_N15G3f_spec07 | B5: 1.0870203 | C5: 1.225027 | D5: 1.1593299 | E5: 1.2454872 | F5: 1.3786238 | G5: 1.2670782 | H5: 1.3518406 | I5: 1.4410401 | J5: y | K5: spec07 | L5: DE | M5: N15G3f | N5: =VLOOKUP(K5,modelNames,2,FALSE) -> BFCS
A6: y_DE_N15G3f_spec08 | B6: 0.97689223 | C6: 1.0388447 | D6: 1.0158731 | E6: 0.92118022 | F6: 0.96297031 | G6: 0.95828231 | H6: 0.91321373 | I6: 1.0155249 | J6: y | K6: spec08 | L6: DE | M6: N15G3f | N6: =VLOOKUP(K6,modelNames,2,FALSE) -> SSSS
A7: y_DE_N15G3f_spec09 | B7: 0.9496043 | C7: 1.0073412 | D7: 0.97637514 | E7: 0.9877844 | F7: 0.99466192 | G7: 1.0457974 | H7: 1.0448649 | I7: 1.013586 | J7: y | K7: spec09 | L7: DE | M7: N15G3f | N7: =VLOOKUP(K7,modelNames,2,FALSE) -> BMS
A8: y_DE_N15G3f_spec10 | B8: 0.95542129 | C8: 1.8127125 | D8: 1.8514791 | E8: 1.8715608 | F8: 1.9616715 | G8: 2.0477328 | H8: 2.0206027 | I8: 2.0896049 | J8: y | K8: spec10 | L8: DE | M8: N15G3f | N8: =VLOOKUP(K8,modelNames,2,FALSE) -> CC
A9: y_DE_N15G3f_spec03 | B9: 1.0274715 | C9: 1.0456869 | D9: 1.0273626 | E9: 0.98028205 | F9: 0.97391618 | G9: 0.98071175 | H9: 0.98293781 | I9: 0.99156274 | J9: y | K9: spec03 | L9: DE | M9: N15G3f | N9: =VLOOKUP(K9,modelNames,2,FALSE) -> POOL
A10: y_FR_N15G3f_spec02 | B10: 1 | C10: 1 | D10: 1 | E10: 1 | F10: 1 | G10: 1 | H10: 1 | I10: 1 | J10: y | K10: spec02 | L10: FR | M10: N15G3f | N10: =VLOOKUP(K10,modelNames,2,FALSE) -> ZS
A11: y_FR_N15G3f_spec01 | B11: 1.0114353 | C11: 1.0112038 | D11: 1.0489783 | E11: 1.0030992 | F11: 0.95884274 | G11: 1.0050542 | H11: 0.94965967 | I11: 0.97820838 | J11: y | K11: spec01 | L11: FR | M11: N15G3f | N11: =VLOOKUP(K11,modelNames,2,FALSE) -> ZS\&POOL
A12: y_FR_N15G3f_spec04 | B12: 0.98259733 | C12: 1.0484339 | D12: 1.0806965 | E12: 1.0065729 | F12: 0.96033722 | G12: 1.0232133 | H12: 1.0096423 | I12: 1.0355854 | J12: y | K12: spec04 | L12: FR | M12: N15G3f | N12: =VLOOKUP(K12,modelNames,2,FALSE) -> ZSGL
A13: y_FR_N15G3f_spec07 | B13: 1.1909051 | C13: 1.5158822 | D13: 1.6274829 | E13: 1.6696786 | F13: 1.6504255 | G13: 1.6558829 | H13: 1.5986419 | I13: 1.6971585 | J13: y | K13: spec07 | L13: FR | M13: N15G3f | N13: =VLOOKUP(K13,modelNames,2,FALSE) -> BFCS
... A405: r_CH_N15G3f_spec03 | B405: 1.0776086 | C405: 1.0872195 | D405: 1.1023436 | E405: 1.0809719 | F405: 1.100423 | G405: 1.1422394 | H405: 1.1706941 | I405: 1.1879427 | J405: r | K405: spec03 | L405: CH | M405: N15G3f | N405: =VLOOKUP(K405,modelNames,2,FALSE) -> POOL
A406: r_CH_N15G3f_spec18 | B406: 0.9665937 | C406: 0.97691701 | D406: 0.99914171 | E406: 0.96473883 | F406: 0.97425244 | G406: 0.97300955 | H406: 0.98684563 | I406: 0.97421517 | J406: r | K406: spec18 | L406: CH | M406: N15G3f | N406: J

Sheet rmsfe_Pivot_T1
S1: 0.1 | AM1: 0.05
A3: Sum of T_1 | B3: Column Labels | S3: Sum of T_1 | T3: Column Labels | AM3: Sum of T_1 | AN3: Column Labels
A4: Row Labels | B4: AG | C4: AT | D4: AU | E4: BR | F4: CA | G4: CH | H4: CN | I4: DE | J4: FR | K4: GB | L4: IN | M4: IT | N4: JP | O4: MX | P4: US | S4: Row Labels | T4: AG | U4: AT | V4: AU | W4: BR | X4: CA | Y4: CH | Z4: CN | AA4: DE | AB4: FR | AC4: GB | AD4: IN | AE4: IT | AF4: JP | AG4: MX | AH4: US | AI4: Grand Total | AM4: Row Labels | AN4: AG | AO4: AT | AP4: AU | AQ4: BR | AR4: CA | AS4: CH | AT4: CN | AU4: DE | AV4: FR | AW4: GB | AX4: IN | AY4: IT | AZ4: JP | BA4: MX | BB4: US | BC4: Grand Total
A5: y | S5: y | T5: 0 | U5: 1 | V5: 1 | W5: 0 | X5: 1 | Y5: 0 | Z5: 0 | AA5: 3 | AB5: 0 | AC5: 0 | AD5: 0 | AE5: 2 | AF5: 3 | AG5: 0 | AH5: 1 | AI5: 12 | AM5: y | AN5: 0 | AO5: 0 | AP5: 1 | AQ5: 0 | AR5: 0 | AS5: 0 | AT5: 0 | AU5: 1 | AV5: 0 | AW5: 0 | AX5: 0 | AY5: 2 | AZ5: 1 | BA5: 0 | BB5: 1 | BC5: 6
A6: ZS | B6: 1 | C6: 1 | D6: 1 | E6: 1 | F6: 1 | G6: 1 | H6: 1 | I6: 1 | J6: 1 | K6: 1 | L6: 1 | M6: 1 | N6: 1 | O6: 1 | P6: 1 | S6: ZS | T6: 0 | U6: 0 | V6: 0 | W6: 0 | X6: 0 | Y6: 0 | Z6: 0 | AA6: 0 | AB6: 0 | AC6: 0 | AD6: 0 | AE6: 0 | AF6: 0 | AG6: 0 | AH6: 0 | AI6: 0 | AM6: ZS | AN6: 0 | AO6: 0 | AP6: 0 | AQ6: 0 | AR6: 0 | AS6: 0 | AT6: 0 | AU6: 0 | AV6: 0 | AW6: 0 | AX6: 0 | AY6: 0 | AZ6: 0 | BA6: 0 | BB6: 0 | BC6: 0
A7: ZS\&POOL | B7: 0.98906183 | C7: 0.97699228 | D7: 0.96592352 | E7: 0.99166505 | F7: 0.97246307 | G7: 1.0322444 | H7: 1.0017493 | I7: 0.96808742 | J7: 1.0019519 | K7: 0.98579759 | L7: 0.97768332 | M7: 0.98595421 | N7: 0.96336126 | O7: 0.9822667 | P7: 0.98206475 | S7: ZS\&POOL | T7: 0 | U7: 0 | V7: 1 | W7: 0 | X7: 1 | Y7: 0 | Z7: 0 | AA7: 1 | AB7: 0 | AC7: 0 | AD7: 0 | AE7: 0 | AF7: 1 | AG7: 0 | AH7: 1 | AI7: 5 | AM7: ZS\&POOL | AN7: 0 | AO7: 0 | AP7: 1 | AQ7: 0 | AR7: 0 | AS7: 0 | AT7: 0 | AU7: 0 | AV7: 0 | AW7: 0 | AX7: 0 | AY7: 0 | AZ7: 1 | BA7: 0 | BB7: 1 | BC7: 3
A8: POOL | B8: 0.99159285 | C8: 0.98969418 | D8: 1.0046956 | E8: 0.99446596 | F8: 1.0602666 | G8: 1.0157567 | H8: 0.97944956 | I8: 0.98280453 | J8: 1.0257085 | K8: 0.99041453 | L8: 1.0389269 | M8: 0.96331259 | N8: 0.96348392 | O8: 1.0002222 | P8: 1.0009473 | S8: POOL | T8: 0 | U8: 0 | V8: 0 | W8: 0 | X8: 0 | Y8: 0 | Z8: 0 | AA8: 0 | AB8: 0 | AC8: 0 | AD8: 0 | AE8: 1 | AF8: 1 | AG8: 0 | AH8: 0 | AI8: 2 | AM8: POOL | AN8: 0 | AO8: 0 | AP8: 0 | AQ8: 0 | AR8: 0 | AS8: 0 | AT8: 0 | AU8: 0 | AV8: 0 | AW8: 0 | AX8: 0 | AY8: 1 | AZ8: 0 | BA8: 0 | BB8: 0 | BC8: 1
A9: ZSGL | B9: 1.0033596 | C9: 0.97784151 | D9: 1.0041148 | E9: 0.99753324 | F9: 1.0176841 | G9: 1.008567 | H9: 0.98686579 | I9: 0.9871982 | J9: 1.013478 | K9: 1.0062204 | L9: 0.98980181 | M9: 1.0146341 | N9: 0.99246481 | O9: 1.0101006 | P9: 1.0083416 | S9: ZSGL | T9: 0 | U9: 1 | V9: 0 | W9: 0 | X9: 0 | Y9: 0 | Z9: 0 | AA9: 0 | AB9: 0 | AC9: 0 | AD9: 0 | AE9: 0 | AF9: 0 | AG9: 0 | AH9: 0 | AI9: 1 | AM9: ZSGL | AN9: 0 | AO9: 0 | AP9: 0 | AQ9: 0 | AR9: 0 | AS9: 0 | AT9: 0 | AU9: 0 | AV9: 0 | AW9: 0 | AX9: 0 | AY9: 0 | AZ9: 0 | BA9: 0 | BB9: 0 | BC9: 0
A10: J | B10: 0.98627065 | C10: 0.96266626 | D10: 0.96950246 | E10: 1.0154966 | F10: 0.99857616 | G10: 1.0841565 | H10: 1.033762 | I10: 0.94034669 | J10: 1.0147695 | K10: 0.97726113 | L10: 1.0312099 | M10: 0.94859568 | N10: 0.96733757 | O10: 0.9814816 | P10: 0.99746083 | S10: J | T10: 0 | U10: 0 | V10: 0 | W10: 0 | X10: 0 | Y10: 0 | Z10: 0 | AA10: 0 | AB10: 0 | AC10: 0 | AD10: 0 | AE10: 1 | AF10: 1 | AG10: 0 | AH10: 0 | AI10: 2 | AM10: J | AN10: 0 | AO10: 0 | AP10: 0 | AQ10: 0 | AR10: 0 | AS10: 0 | AT10: 0 | AU10: 0 | AV10: 0 | AW10: 0 | AX10: 0 | AY10: 1 | AZ10: 0 | BA10: 0 | BB10: 0 | BC10: 1
A11: BFCS | B11: 1.1256729 | C11: 0.94966489 | D11: 0.97017014 | E11: 1.0583184 | F11: 1.0558248 | G11: 1.0209021 | H11: 1.0861227 | I11: 0.95894221 | J11: 1.0777371 | K11: 1.0541974 | L11: 0.96468704 | M11: 1.0175976 | N11: 0.95968781 | O11: 1.0004289 | P11: 1.1079436 | S11: BFCS | T11: 0 | U11: 0 | V11: 0 | W11: 0 | X11: 0 | Y11: 0 | Z11: 0 | AA11: 1 | AB11: 0 | AC11: 0 | AD11: 0 | AE11: 0 | AF11: 0 | AG11: 0 | AH11: 0 | AI11: 1 | AM11: BFCS | AN11: 0 | AO11: 0 | AP11: 0 | AQ11: 0 | AR11: 0 | AS11: 0 | AT11: 0 | AU11: 0 | AV11: 0 | AW11: 0 | AX11: 0 | AY11: 0 | AZ11: 0 | BA11: 0 | BB11: 0 | BC11: 0
A12: SSSS | B12: 1.1840478 | C12: 0.98170779 | D12: 1.3886899 | E12: 7.8809123 | F12: 1.3203544 | G12: 1.0702148 | H12: 1.2502026 | I12: 0.98328678 | J12: 1.6190746 | K12: 1.2841811 | L12: 1.1360496 | M12: 1.5811516 | N12: 0.99489862 | O12: 2.4008005 | P12: 1.2576171 | S12: SSSS | T12: 0 | U12: 0 | V12: 0 | W12: 0 | X12: 0 | Y12: 0 | Z12: 0 | AA12: 0 | AB12: 0 | AC12: 0 | AD12: 0 | AE12: 0 | AF12: 0 | AG12: 0 | AH12: 0 | AI12: 0 | AM12: SSSS | AN12: 0 | AO12: 0 | AP12: 0 | AQ12: 0 | AR12: 0 | AS12: 0 | AT12: 0 | AU12: 0 | AV12: 0 | AW12: 0 | AX12: 0 | AY12: 0 | AZ12: 0 | BA12: 0 | BB12: 0 | BC12: 0
A13: BMS | B13: 1.1293641 | C13: 0.96651499 | D13: 1.233934 | E13: 1.4718089 | F13: 0.9931411 | G13: 1.1514251 | H13: 1.0997746 | I13: 0.92441025 | J13: 1.0695817 | K13: 1.061302 | L13: 1.0026721 | M13: 1.0919533 | N13: 1.0277552 | O13: 0.94929525 | P13: 1.2657967 | S13: BMS | T13: 0 | U13: 0 | V13: 0 | W13: 0 | X13: 0 | Y13: 0 | Z13: 0 | AA13: 1 | AB13: 0 | AC13: 0 | AD13: 0 | AE13: 0 | AF13: 0 | AG13: 0 | AH13: 0 | AI13: 1 | AM13: BMS | AN13: 0 | AO13: 0 | AP13: 0 | AQ13: 0 | AR13: 0 | AS13: 0 | AT13: 0 | AU13: 1 | AV13: 0 | AW13: 0 | AX13: 0 | AY13: 0 | AZ13: 0 | BA13: 0 | BB13: 0 | BC13: 1
A14: CC | B14: 1.3315833 | C14: 0.99984755 | D14: 1.4298072 | E14: 2.9337657 | F14: 0.99436648 | G14: 1.1175426 | H14: 1.0992701 | I14: 0.97111272 | J14: 1.2523473 | K14: 1.1634489 | L14: 1.050049 | M14: 1.1281171 | N14: 1.0244718 | O14: 1.373002 | P14: 1.2874379 | S14: CC | T14: 0 | U14: 0 | V14: 0 | W14: 0 | X14: 0 | Y14: 0 | Z14: 0 | AA14: 0 | AB14: 0 | AC14: 0 | AD14: 0 | AE14: 0 | AF14: 0 | AG14: 0 | AH14: 0 | AI14: 0 | AM14: CC | AN14: 0 | AO14: 0 | AP14: 0 | AQ14: 0 | AR14: 0 | AS14: 0 | AT14: 0 | AU14: 0 | AV14: 0 | AW14: 0 | AX14: 0 | AY14: 0 | AZ14: 0 | BA14: 0 | BB14: 0 | BC14: 0
A15: Dp | S15: Dp | T15: 3 | U15: 1 | V15: 2 | W15: 3 | X15: 0 | Y15: 0 | Z15: 0 | AA15: 1 | AB15: 1 | AC15: 0 | AD15: 2 | AE15: 1 | AF15: 0 | AG15: 4 | AH15: 0 | AI15: 18 | AM15: Dp | AN15: 2 | AO15: 1 | AP15: 1 | AQ15: 3 | AR15: 0 | AS15: 0 | AT15: 0 | AU15: 1 | AV15: 0 | AW15: 0 | AX15: 2 | AY15: 1 | AZ15: 0 | BA15: 4 | BB15: 0 | BC15: 15
A16: ZS | B16: 1 | C16: 1 | D16: 1 | E16: 1 | F16: 1 | G16: 1 | H16: 1 | I16: 1 | J16: 1 | K16: 1 | L16: 1 | M16: 1 | N16: 1 | O16: 1 | P16: 1 | S16: ZS | T16: 0 | U16: 0 | V16: 0 | W16: 0 | X16: 0 | Y16: 0 | Z16: 0 | AA16: 0 | AB16: 0 | AC16: 0 | AD16: 0 | AE16: 0 | AF16: 0 | AG16: 0 | AH16: 0 | AI16: 0 | AM16: ZS | AN16: 0 | AO16: 0 | AP16: 0 | AQ16: 0 | AR16: 0 | AS16: 0 | AT16: 0 | AU16: 0 | AV16: 0 | AW16: 0 | AX16: 0 | AY16: 0 | AZ16: 0 | BA16: 0 | BB16: 0 | BC16: 0
A17: ZS\&POOL | B17: 0.837373 | C17: 0.98386149 | D17: 1.0108825 | E17: 0.92480665 | F17: 0.9946252 | G17: 0.99910887 | H17: 0.98728239 | I17: 1.012214 | J17: 0.96620633 | K17: 1.0040174 | L17: 0.9326187 | M17: 0.91400344 | N17: 1.0013097 | O17: 0.94965064 | P17: 0.99239094 | S17: ZS\&POOL | T17: 1 | U17: 1 | V17: 0 | W17: 1 | X17: 0 | Y17: 0 | Z17: 0 | AA17: 0 | AB17: 1 | AC17: 0 | AD17: 1 | AE17: 1 | AF17: 0 | AG17: 1 | AH17: 0 | AI17: 7 | AM17: ZS\&POOL | AN17: 0 | AO17: 1 | AP17: 0 | AQ17: 1 | AR17: 0 | AS17: 0 | AT17: 0 | AU17: 0 | AV17: 0 | AW17: 0 | AX17: 1 | AY17: 1 | AZ17: 0 | BA17: 1 | BB17: 0 | BC17: 5
A18: POOL | B18: 0.88312533 | C18: 0.98128278 | D18: 0.99389774 | E18: 0.85264128 | F18: 1.005789 | G18: 1.0189931 | H18: 1.0278712 | I18: 1.016309 | J18: 1.0063413 | K18: 1.0025179 | L18: 0.98292745 | M18: 0.98275454 | N18: 0.9754293 | O18: 0.71307862 | P18: 0.99998452 | S18: POOL | T18: 0 | U18: 0 | V18: 0 | W18: 1 | X18: 0 | Y18: 0 | Z18: 0 | AA18: 0 | AB18: 0 | AC18: 0 | AD18: 0 | AE18: 0 | AF18: 0 | AG18: 1 | AH18: 0 | AI18: 2 | AM18: POOL | AN18: 0 | AO18: 0 | AP18: 0 | AQ18: 1 | AR18: 0 | AS18: 0 | AT18: 0 | AU18: 0 | AV18: 0 | AW18: 0 | AX18: 0 | AY18: 0 | AZ18: 0 | BA18: 1 | BB18: 0 | BC18: 2
A19: ZSGL | B19: 0.86456609 | C19: 1.0002011 | D19: 0.98207424 | E19: 0.98249974 | F19: 1.0023734 | G19: 1.005906 | H19: 1.0212853 | I19: 1.0204362 | J19: 1.017754 | K19: 0.98974856 | L19: 1.0323659 | M19: 1.0237121 | N19: 0.98338203 | O19: 0.73989578 | P19: 0.99619082 | S19: ZSGL | T19: 1 | U19: 0 | V19: 1 | W19: 0 | X19: 0 | Y19: 0 | Z19: 0 | AA19: 0 | AB19: 0 | AC19: 0 | AD19: 0 | AE19: 0 | AF19: 0 | AG19: 1 | AH19: 0 | AI19: 3 | AM19: ZSGL | AN19: 1 | AO19: 0 | AP19: 0 | AQ19: 0 | AR19: 0 | AS19: 0 | AT19: 0 | AU19: 0 | AV19: 0 | AW19: 0 | AX19: 0 | AY19: 0 | AZ19: 0 | BA19: 1 | BB19: 0 | BC19: 2
A20: J | B20: 0.7845363 | C20: 1.1289723 | D20: 1.0402689 | E20: 0.45268636 | F20: 1.0491842 | G20: 0.95185497 | H20: 1.0223443 | I20: 1.1198447 | J20: 1.073061 | K20: 1.0879171 | L20: 0.88997787 | M20: 0.97197355 | N20: 1.0735342 | O20: 0.8253333 | P20: 1.0501716 | S20: J | T20: 1 | U20: 0 | V20: 0 | W20: 1 | X20: 0 | Y20: 0 | Z20: 0 | AA20: 0 | AB20: 0 | AC20: 0 | AD20: 1 | AE20: 0 | AF20: 0 | AG20: 1 | AH20: 0 | AI20: 4 | AM20: J | AN20: 1 | AO20: 0 | AP20: 0 | AQ20: 1 | AR20: 0 | AS20: 0 | AT20: 0 | AU20: 0 | AV20: 0 | AW20: 0 | AX20: 1 | AY20: 0 | AZ20: 0 | BA20: 1 | BB20: 0 | BC20: 4
A21: BFCS | B21: 3.8508057 | C21: 1.2081407 | D21: 1.206697 | E21: 7.7790285 | F21: 1.2184219 | G21: 1.6694102 | H21: 1.5168987 | I21: 1.2148153 | J21: 1.7501219 | K21: 2.1995598 | L21: 1.0619849 | M21: 2.8626209 | N21: 1.1316903 | O21: 6.5436337 | P21: 1.2218966 | S21: BFCS | T21: 0 | U21: 0 | V21: 0 | W21: 0 | X21: 0 | Y21: 0 | Z21: 0 | AA21: 0 | AB21: 0 | AC21: 0 | AD21: 0 | AE21: 0 | AF21: 0 | AG21: 0 | AH21: 0 | AI21: 0 | AM21: BFCS | AN21: 0 | AO21: 0 | AP21: 0 | AQ21: 0 | AR21: 0 | AS21: 0 | AT21: 0 | AU21: 0 | AV21: 0 | AW21: 0 | AX21: 0 | AY21: 0 | AZ21: 0 | BA21: 0 | BB21: 0 | BC21: 0
A22: SSSS | B22: 2.1178336 | C22: 1.3315087 | D22: 0.8957881 | E22: 3.3130996 | F22: 0.97950679 | G22: 0.99811461 | H22: 1.1210709 | I22: 1.1491992 | J22: 1.0540687 | K22: 1.337986 | L22: 1.0221667 | M22: 1.32696 | N22: 1.019257 | O22: 2.7815216 | P22: 0.99194038 | S22: SSSS | T22: 0 | U22: 0 | V22: 1 | W22: 0 | X22: 0 | Y22: 0 | Z22: 0 | AA22: 0 | AB22: 0 | AC22: 0 | AD22: 0 | AE22: 0 | AF22: 0 | AG22: 0 | AH22: 0 | AI22: 1 | AM22: SSSS | AN22: 0 | AO22: 0 | AP22: 1 | AQ22: 0 | AR22: 0 | AS22: 0 | AT22: 0 | AU22: 0 | AV22: 0 | AW22: 0 | AX22: 0 | AY22: 0 | AZ22: 0 | BA22: 0 | BB22: 0 | BC22: 1
A23: BMS | B23: 2.0945428 | C23: 1.0519692 | D23: 0.94949534 | E23: 4.9174474 | F23: 1.0006595 | G23: 1.177622 | H23: 1.4165101 | I23: 0.94067067 | J23: 1.0559616 | K23: 1.4192375 | L23: 0.92518253 | M23: 1.3123767 | N23: 1.0099219 | O23: 2.5527161 | P23: 1.0981952 | S23: BMS | T23: 0 | U23: 0 | V23: 0 | W23: 0 | X23: 0 | Y23: 0 | Z23: 0 | AA23: 1 | AB23: 0 | AC23: 0 | AD23: 0 | AE23: 0 | AF23: 0 | AG23: 0 | AH23: 0 | AI23: 1 | AM23: BMS | AN23: 0 | AO23: 0 | AP23: 0 | AQ23: 0 | AR23: 0 | AS23: 0 | AT23: 0 | AU23: 1 | AV23: 0 | AW23: 0 | AX23: 0 | AY23: 0 | AZ23: 0 | BA23: 0 | BB23: 0 | BC23: 1
A24: CC | B24: 3.5487105 | C24: 1.1064808 | D24: 0.96233388 | E24: 7.5878016 | F24: 0.99179046 | G24: 1.4241666 | H24: 1.3821561 | I24: 1.1973233 | J24: 1.1337011 | K24: 1.3742212 | L24: 1.0612179 | M24: 1.3001141 | N24: 1.3093427 | O24: 4.630634 | P24: 0.96316075 | S24: CC | T24: 0 | U24: 0 | V24: 0 | W24: 0 | X24: 0 | Y24: 0 | Z24: 0 | AA24: 0 | AB24: 0 | AC24: 0 | AD24: 0 | AE24: 0 | AF24: 0 | AG24: 0 | AH24: 0 | AI24: 0 | AM24: CC | AN24: 0 | AO24: 0 | AP24: 0 | AQ24: 0 | AR24: 0 | AS24: 0 | AT24: 0 | AU24: 0 | AV24: 0 | AW24: 0 | AX24: 0 | AY24: 0 | AZ24: 0 | BA24: 0 | BB24: 0 | BC24: 0
A25: r | S25: r | T25: 4 | U25: 3 | V25: 0 | W25: 4 | X25: 2 | Y25: 1 | Z25: 2 | AA25: 1 | AB25: 0 | AC25: 3 | AD25: 2 | AE25: 0 | AF25: 1 | AG25: 4 | AH25: 3 | AI25: 30 | AM25: r | AN25: 3 | AO25: 3 | AP25: 0 | AQ25: 3 | AR25: 1 | AS25: 1 | AT25: 1 | AU25: 1 | AV25: 0 | AW25: 3 | AX25: 2 | AY25: 0 | AZ25: 1 | BA25: 4 | BB25: 3 | BC25: 26
A26: ZS | B26: 1 | C26: 1 | D26: 1 | E26: 1 | F26: 1 | G26: 1 | H26: 1 | I26: 1 | J26: 1 | K26: 1 | L26: 1 | M26: 1 | N26: 1 | O26: 1 | P26: 1 | S26: ZS | T26: 0 | U26: 0 | V26: 0 | W26: 0 | X26: 0 | Y26: 0 | Z26: 0 | AA26: 0 | AB26: 0 | AC26: 0 | AD26: 0 | AE26: 0 | AF26: 0 | AG26: 0 | AH26: 0 | AI26: 0 | AM26: ZS | AN26: 0 | AO26: 0 | AP26: 0 | AQ26: 0 | AR26: 0 | AS26: 0 | AT26: 0 | AU26: 0 | AV26: 0 | AW26: 0 | AX26: 0 | AY26: 0 | AZ26: 0 | BA26: 0 | BB26: 0 | BC26: 0
A27: ZS\&POOL | B27: 0.74409767 | C27: 1.0269023 | D27: 0.96069195 | E27: 0.89179243 | F27: 0.92112628 | G27: 0.96020164 | H27: 0.93940132 | I27: 1.0545602 | J27: 1.0253011 | K27: 0.91918354 | L27: 0.97592434 | M27: 0.95654271 | N27: 1.2068251 | O27: 0.85145031 | P27: 0.93238273 | S27: ZS\&POOL | T27: 1 | U27: 0 | V27: 0 | W27: 1 | X27: 0 | Y27: 1 | Z27: 1 | AA27: 0 | AB27: 0 | AC27: 1 | AD27: 1 | AE27: 0 | AF27: 0 | AG27: 1 | AH27: 1 | AI27: 8 | AM27: ZS\&POOL | AN27: 0 | AO27: 0 | AP27: 0 | AQ27: 1 | AR27: 0 | AS27: 1 | AT27: 1 | AU27: 0 | AV27: 0 | AW27: 1 | AX27: 1 | AY27: 0 | AZ27: 0 | BA27: 1 | BB27: 1 | BC27: 7
A28: POOL | B28: 0.61160014 | C28: 0.93087654 | D28: 0.97551276 | E28: 0.78498146 | F28: 0.96783506 | G28: 0.99687398 | H28: 0.99644466 | I28: 0.99961366 | J28: 0.97606708 | K28: 0.85577556 | L28: 1.0009545 | M28: 1.0127247 | N28: 1.1466807 | O28: 0.58506175 | P28: 0.93786326 | S28: POOL | T28: 1 | U28: 1 | V28: 0 | W28: 1 | X28: 0 | Y28: 0 | Z28: 0 | AA28: 0 | AB28: 0 | AC28: 1 | AD28: 0 | AE28: 0 | AF28: 0 | AG28: 1 | AH28: 1 | AI28: 6 | AM28: POOL | AN28: 1 | AO28: 1 | AP28: 0 | AQ28: 1 | AR28: 0 | AS28: 0 | AT28: 0 | AU28: 0 | AV28: 0 | AW28: 1 | AX28: 0 | AY28: 0 | AZ28: 0 | BA28: 1 | BB28: 1 | BC28: 6
A29: ZSGL | B29: 0.775782 | C29: 0.96876718 | D29: 1.0211558 | E29: 0.95373235 | F29: 0.93562797 | G29: 0.98401974 | H29: 0.98992679 | I29: 0.93323542 | J29: 1.0335083 | K29: 0.99895607 | L29: 0.98785124 | M29: 1.0039362 | N29: 0.90361881 | O29: 0.81267769 | P29: 1.0210571 | S29: ZSGL | T29: 1 | U29: 1 | V29: 0 | W29: 1 | X29: 1 | Y29: 0 | Z29: 1 | AA29: 1 | AB29: 0 | AC29: 0 | AD29: 1 | AE29: 0 | AF29: 1 | AG29: 1 | AH29: 0 | AI29: 9 | AM29: ZSGL | AN29: 1 | AO29: 1 | AP29: 0 | AQ29: 0 | AR29: 1 | AS29: 0 | AT29: 0 | AU29: 1 | AV29: 0 | AW29: 0 | AX29: 1 | AY29: 0 | AZ29: 1 | BA29: 1 | BB29: 0 | BC29: 7
A30: J | B30: 0.35073195 | C30: 0.88639114 | D30: 0.94486428 | E30: 0.19772093 | F30: 0.83440251 | G30: 0.97976232 | H30: 1.0614569 | I30: 0.9677479 | J30: 1.0212376 | K30: 0.75985555 | L30: 0.98665247 | M30: 0.97601641 | N30: 0.97343564 | O30: 0.3907503 | P30: 0.80889029 | S30: J | T30: 1 | U30: 1 | V30: 0 | W30: 1 | X30: 1 | Y30: 0 | Z30: 0 | AA30: 0 | AB30: 0 | AC30: 1 | AD30: 0 | AE30: 0 | AF30: 0 | AG30: 1 | AH30: 1 | AI30: 7 | AM30: J | AN30: 1 | AO30: 1 | AP30: 0 | AQ30: 1 | AR30: 0 | AT30: 0 | AU30: 0 | AV30: 0 | AW30: 1 | AX30: 0 | AY30: 0 | AZ30: 0 | BA30: 1 | BB30: 1 | BC30: 6
A31: BFCS | B31: 2.529893 | C31: 6.0631334 | D31: 3.8910381 | E31: 5.9666496 | F31: 8.2143948 | G31: 5.4202435 | H31: 8.2803611 | I31: 5.2949445 | J31: 9.5354483 | K31: 8.9150244 | L31: 1.8967556 | M31: 4.8437516 | N31: 3.4530723 | O31: 8.2704175 | P31: 5.8990834 | S31: BFCS | T31: 0 | U31: 0 | V31: 0 | W31: 0 | X31: 0 | Y31: 0 | Z31: 0 | AA31: 0 | AB31: 0 | AC31: 0 | AD31: 0 | AE31: 0 | AF31: 0 | AG31: 0 | AH31: 0 | AI31: 0 | AM31: BFCS | AN31: 0 | AO31: 0 | AP31: 0 | AQ31: 0 | AR31: 0 | AS31: 0 | AT31: 0 | AU31: 0 | AV31: 0 | AW31: 0 | AX31: 0 | AY31: 0 | AZ31: 0 | BA31: 0 | BB31: 0 | BC31: 0
A32: SSSS | B32: 1.9115018 | C32: 1.947349 | D32: 2.0458416 | E32: 2.2912538 | F32: 2.044568 | G32: 1.1270878 | H32: 1.9808073 | I32: 1.9656182 | J32: 2.3523063 | K32: 1.8449146 | L32: 0.99813245 | M32: 1.8099433 | N32: 2.4435262 | O32: 1.9117812 | P32: 1.7766688 | S32: SSSS | T32: 0 | U32: 0 | V32: 0 | W32: 0 | X32: 0 | Y32: 0 | Z32: 0 | AA32: 0 | AB32: 0 | AC32: 0 | AD32: 0 | AE32: 0 | AF32: 0 | AG32: 0 | AH32: 0 | AI32: 0 | AM32: SSSS | AN32: 0 | AO32: 0 | AP32: 0 | AQ32: 0 | AR32: 0 | AS32: 0 | AT32: 0 | AU32: 0 | AV32: 0 | AW32: 0 | AX32: 0 | AY32: 0 | AZ32: 0 | BA32: 0 | BB32: 0 | BC32: 0
A33: BMS | B33: 1.2871683 | C33: 3.7947725 | D33: 2.7176301 | E33: 4.9756427 | F33: 3.617438 | G33: 2.2649841 | H33: 3.8518544 | I33: 3.4809744 | J33: 4.6835017 | K33: 3.9345268 | L33: 1.5208948 | M33: 2.7856864 | N33: 3.8770339 | O33: 3.0299689 | P33: 3.0685942 | S33: BMS | T33: 0 | U33: 0 | V33: 0 | W33: 0 | X33: 0 | Y33: 0 | Z33: 0 | AA33: 0 | AB33: 0 | AC33: 0 | AD33: 0 | AE33: 0 | AF33: 0 | AG33: 0 | AH33: 0 | AI33: 0 | AM33: BMS | AN33: 0 | AO33: 0 | AP33: 0 | AQ33: 0 | AR33: 0 | AS33: 0 | AT33: 0 | AU33: 0 | AV33: 0 | AW33: 0 | AX33: 0 | AY33: 0 | AZ33: 0 | BA33: 0 | BB33: 0 | BC33: 0
A34: CC | B34: 2.2195227 | C34: 5.3504471 | D34: 3.6028883 | E34: 5.0770316 | F34: 5.4065889 | G34: 2.1768079 | H34: 5.7240926 | I34: 5.0256096 | J34: 7.7864168 | K34: 5.4951116 | L34: 1.8644738 | M34: 3.7359174 | N34: 9.1709139 | O34: 5.476017 | P34: 3.8178104 | S34: CC | T34: 0 | U34: 0 | V34: 0 | W34: 0 | X34: 0 | Y34: 0 | Z34: 0 | AA34: 0 | AB34: 0 | AC34: 0 | AD34: 0 | AE34: 0 | AF34: 0 | AG34: 0 | AH34: 0 | AI34: 0 | AM34: CC | AN34: 0 | AO34: 0 | AP34: 0 | AQ34: 0 | AR34: 0 | AS34: 0 | AT34: 0 | AU34: 0 | AV34: 0 | AW34: 0 | AX34: 0 | AY34: 0 | AZ34: 0 | BA34: 0 | BB34: 0 | BC34: 0
S35: Grand Total | T35: 7 | U35: 5 | V35: 3 | W35: 7 | X35: 3 | Y35: 1 | Z35: 2 | AA35: 5 | AB35: 1 | AC35: 3 | AD35: 4 | AE35: 3 | AF35: 4 | AG35: 8 | AH35: 4 | AI35: 60 | AM35: Grand Total | AN35: 5 | AO35: 4 | AP35: 2 | AQ35: 6 | AR35: 1 | AS35: 1 | AT35: 1 | AU35: 3 | AV35: 0 | AW35: 3 | AX35: 4 | AY35: 3 | AZ35: 2 | BA35: 8 | BB35: 4 | BC35: 47

Sheet rmsfe_Pivot_T4
S1: 0.1 | AM1: 0.05
A3: Sum of T_4 | B3: Column Labels | S3: Sum of T_4 | T3: Column Labels | AM3: Sum of T_4 | AN3: Column Labels
A4: Row Labels | B4: AG | C4: AT | D4: AU | E4: BR | F4: CA | G4: CH | H4: CN | I4: DE | J4: FR | K4: GB | L4: IN | M4: IT | N4: JP | O4: MX | P4: US | S4: Row Labels | T4: AG | U4: AT | V4: AU | W4: BR | X4: CA | Y4: CH | Z4: CN | AA4: DE | AB4: FR | AC4: GB | AD4: IN | AE4: IT | AF4: JP | AG4: MX | AH4: US | AI4: Grand Total | AM4: Row Labels | AN4: AG | AO4: AT | AP4: AU | AQ4: BR | AR4: CA | AS4: CH | AT4: CN | AU4: DE | AV4: FR | AW4: GB | AX4: IN | AY4: IT | AZ4: JP | BA4: MX | BB4: US | BC4: Grand Total
A5: y | S5: y | T5: 2 | U5: 0 | V5: 3 | W5: 1 | X5: 3 | Y5: 0 | Z5: 0 | AA5: 4 | AB5: 1 | AC5: 0 | AD5: 0 | AE5: 3 | AF5: 2 | AG5: 0 | AH5: 1 | AI5: 20 | AM5: y | AN5: 2 | AO5: 0 | AP5: 2 | AQ5: 1 | AR5: 3 | AS5: 0 | AT5: 0 | AU5: 0 | AV5: 1 | AW5: 0 | AX5: 0 | AY5: 2 | AZ5: 1 | BA5: 0 | BB5: 1 | BC5: 13
A6: ZS | B6: 1 | C6: 1 | D6: 1 | E6: 1 | F6: 1 | G6: 1 | H6: 1 | I6: 1 | J6: 1 | K6: 1 | L6: 1 | M6: 1 | N6: 1 | O6: 1 | P6: 1 | S6: ZS | T6: 0 | U6: 0 | V6: 0 | W6: 0 | X6: 0 | Y6: 0 | Z6: 0 | AA6: 0 | AB6: 0 | AC6: 0 | AD6: 0 | AE6: 0 | AF6: 0 | AG6: 0 | AH6: 0 | AI6: 0 | AM6: ZS | AN6: 0 | AO6: 0 | AP6: 0 | AQ6: 0 | AR6: 0 | AS6: 0 | AT6: 0 | AU6: 0 | AV6: 0 | AW6: 0 | AX6: 0 | AY6: 0 | AZ6: 0 | BA6: 0 | BB6: 0 | BC6: 0
A7: ZS\&POOL | B7: 0.98585953 | C7: 0.9951101 | D7: 0.9575379 | E7: 0.98320739 | F7: 0.94322066 | G7: 1.0043898 | H7: 1.0272144 | I7: 0.97031983 | J7: 0.99955168 | K7: 0.98715162 | L7: 0.99509102 | M7: 1.0035078 | N7: 0.98493233 | O7: 1.0032397 | P7: 0.99671766 | S7: ZS\&POOL | T7: 1 | U7: 0 | V7: 1 | W7: 0 | X7: 1 | Y7: 0 | Z7: 0 | AA7: 1 | AB7: 0 | AC7: 0 | AD7: 0 | AE7: 0 | AF7: 0 | AG7: 0 | AH7: 0 | AI7: 4 | AM7: ZS\&POOL | AN7: 1 | AO7: 0 | AP7: 1 | AQ7: 0 | AR7: 1 | AS7: 0 | AT7: 0 | AU7: 0 | AV7: 0 | AW7: 0 | AX7: 0 | AY7: 0 | AZ7: 0 | BA7: 0 | BB7: 0 | BC7: 3
A8: POOL | B8: 0.99252785 | C8: 1.0046352 | D8: 1.0310991 | E8: 0.9909223 | F8: 1.0089333 | G8: 1.0233882 | H8: 1.0096658 | I8: 0.98620953 | J8: 1.0379374 | K8: 0.99368872 | L8: 0.98621418 | M8: 0.96811557 | N8: 0.94462565 | O8: 0.99784814 | P8: 1.0007679 | S8: POOL | T8: 1 | U8: 0 | V8: 0 | W8: 1 | X8: 0 | Y8: 0 | Z8: 0 | AA8: 0 | AB8: 0 | AC8: 0 | AD8: 0 | AE8: 1 | AF8: 1 | AG8: 0 | AH8: 0 | AI8: 4 | AM8: POOL | AN8: 1 | AO8: 0 | AP8: 0 | AQ8: 1 | AR8: 0 | AS8: 0 | AT8: 0 | AU8: 0 | AV8: 0 | AW8: 0 | AX8: 0 | AY8: 0 | AZ8: 0 | BA8: 0 | BB8: 0 | BC8: 2
A9: ZSGL | B9: 0.99456348 | C9: 0.99708308 | D9: 1.009943 | E9: 0.9975371 | F9: 1.0265893 | G9: 1.0044035 | H9: 0.99963401 | I9: 0.98245249 | J9: 1.0083154 | K9: 0.99697395 | L9: 1.0029849 | M9: 0.99710681 | N9: 0.97212871 | O9: 1.0035386 | P9: 0.99526651 | S9: ZSGL | T9: 0 | U9: 0 | V9: 0 | W9: 0 | X9: 0 | Y9: 0 | Z9: 0 | AA9: 0 | AB9: 0 | AC9: 0 | AD9: 0 | AE9: 0 | AF9: 1 | AG9: 0 | AH9: 1 | AI9: 2 | AM9: ZSGL | AN9: 0 | AO9: 0 | AP9: 0 | AQ9: 0 | AR9: 0 | AS9: 0 | AT9: 0 | AU9: 0 | AV9: 0 | AW9: 0 | AX9: 0 | AY9: 0 | AZ9: 1 | BA9: 0 | BB9: 1 | BC9: 2
A10: J | B10: 0.97357571 | C10: 0.98559247 | D10: 0.92566441 | E10: 1.0178117 | F10: 0.92148723 | G10: 0.99850204 | H10: 1.1287107 | I10: 0.96812799 | J10: 0.99461421 | K10: 0.99072493 | L10: 1.0355262 | M10: 0.97685567 | N10: 0.97226645 | O10: 0.98703892 | P10: 0.99759885 | S10: J | T10: 0 | U10: 0 | V10: 1 | W10: 0 | X10: 1 | Y10: 0 | Z10: 0 | AA10: 1 | AB10: 0 | AC10: 0 | AD10: 0 | AE10: 1 | AF10: 0 | AG10: 0 | AH10: 0 | AI10: 4 | AM10: J | AN10: 0 | AO10: 0 | AP10: 1 | AQ10: 0 | AR10: 1 | AS10: 0 | AT10: 0 | AU10: 0 | AV10: 0 | AW10: 0 | AX10: 0 | AY10: 1 | AZ10: 0 | BA10: 0 | BB10: 0 | BC10: 3
A11: BFCS | B11: 0.9930018 | C11: 0.99126232 | D11: 0.94156075 | E11: 0.98336082 | F11: 0.88311517 | G11: 1.0207528 | H11: 1.0861519 | I11: 0.96166641 | J11: 0.97441348 | K11: 0.98683147 | L11: 1.0299281 | M11: 0.96764544 | N11: 0.99042251 | O11: 1.0372873 | P11: 0.98174106 | S11: BFCS | T11: 0 | U11: 0 | V11: 1 | W11: 0 | X11: 1 | Y11: 0 | Z11: 0 | AA11: 1 | AB11: 1 | AC11: 0 | AD11: 0 | AE11: 1 | AF11: 0 | AG11: 0 | AH11: 0 | AI11: 5 | AM11: BFCS | AN11: 0 | AO11: 0 | AP11: 0 | AQ11: 0 | AR11: 1 | AS11: 0 | AT11: 0 | AU11: 0 | AV11: 1 | AW11: 0 | AX11: 0 | AY11: 1 | AZ11: 0 | BA11: 0 | BB11: 0 | BC11: 3
A12: SSSS | B12: 1.1473636 | C12: 1.0534924 | D12: 1.1720303 | E12: 8.3450528 | F12: 1.0839762 | G12: 1.0263316 | H12: 1.2047919 | I12: 0.96145517 | J12: 1.1858916 | K12: 1.1218394 | L12: 1.1223523 | M12: 1.3716258 | N12: 0.97397444 | O12: 2.1359214 | P12: 1.0266943 | S12: SSSS | T12: 0 | U12: 0 | V12: 0 | W12: 0 | X12: 0 | Y12: 0 | Z12: 0 | AA12: 0 | AB12: 0 | AC12: 0 | AD12: 0 | AE12: 0 | AF12: 0 | AG12: 0 | AH12: 0 | AI12: 0 | AM12: SSSS | AN12: 0 | AO12: 0 | AP12: 0 | AQ12: 0 | AR12: 0 | AS12: 0 | AT12: 0 | AU12: 0 | AV12: 0 | AW12: 0 | AX12: 0 | AY12: 0 | AZ12: 0 | BA12: 0 | BB12: 0 | BC12: 0
A13: BMS | B13: 1.0907112 | C13: 0.96878933 | D13: 1.2351877 | E13: 1.1260713 | F13: 1.0515592 | G13: 1.0766762 | H13: 1.1298163 | I13: 0.96671863 | J13: 1.0474823 | K13: 1.025193 | L13: 1.0128892 | M13: 0.99859954 | N13: 0.9629696 | O13: 1.0204384 | P13: 1.054463 | S13: BMS | T13: 0 | U13: 0 | V13: 0 | W13: 0 | X13: 0 | Y13: 0 | Z13: 0 | AA13: 1 | AB13: 0 | AC13: 0 | AD13: 0 | AE13: 0 | AF13: 0 | AG13: 0 | AH13: 0 | AI13: 1 | AM13: BMS | AN13: 0 | AO13: 0 | AP13: 0 | AQ13: 0 | AR13: 0 | AS13: 0 | AT13: 0 | AU13: 0 | AV13: 0 | AW13: 0 | AX13: 0 | AY13: 0 | AZ13: 0 | BA13: 0 | BB13: 0 | BC13: 0
A14: CC | B14: 1.4539449 | C14: 1.6668856 | D14: 2.938335 | E14: 2.1132653 | F14: 2.6729158 | G14: 1.9170075 | H14: 1.8233119 | I14: 2.00621 | J14: 2.904476 | K14: 2.220655 | L14: 1.5272563 | M14: 2.6464487 | N14: 2.1310226 | O14: 2.1826573 | P14: 2.6855486 | S14: CC | T14: 0 | U14: 0 | V14: 0 | W14: 0 | X14: 0 | Y14: 0 | Z14: 0 | AA14: 0 | AB14: 0 | AC14: 0 | AD14: 0 | AE14: 0 | AF14: 0 | AG14: 0 | AH14: 0 | AI14: 0 | AM14: CC | AN14: 0 | AO14: 0 | AP14: 0 | AQ14: 0 | AR14: 0 | AS14: 0 | AT14: 0 | AU14: 0 | AV14: 0 | AW14: 0 | AX14: 0 | AY14: 0 | AZ14: 0 | BA14: 0 | BB14: 0 | BC14: 0
A15: Dp | S15: Dp | T15: 3 | U15: 0 | V15: 0 | W15: 2 | X15: 0 | Y15: 0 | Z15: 0 | AA15: 0 | AB15: 1 | AC15: 1 | AD15: 3 | AE15: 1 | AF15: 0 | AG15: 4 | AH15: 0 | AI15: 15 | AM15: Dp | AN15: 1 | AO15: 0 | AP15: 0 | AQ15: 2 | AR15: 0 | AS15: 0 | AT15: 0 | AU15: 0 | AV15: 1 | AW15: 1 | AX15: 2 | AY15: 1 | AZ15: 0 | BA15: 4 | BB15: 0 | BC15: 12
A16: ZS | B16: 1 | C16: 1 | D16: 1 | E16: 1 | F16: 1 | G16: 1 | H16: 1 | I16: 1 | J16: 1 | K16: 1 | L16: 1 | M16: 1 | N16: 1 | O16: 1 | P16: 1 | S16: ZS | T16: 0 | U16: 0 | V16: 0 | W16: 0 | X16: 0 | Y16: 0 | Z16: 0 | AA16: 0 | AB16: 0 | AC16: 0 | AD16: 0 | AE16: 0 | AF16: 0 | AG16: 0 | AH16: 0 | AI16: 0 | AM16: ZS | AN16: 0 | AO16: 0 | AP16: 0 | AQ16: 0 | AR16: 0 | AS16: 0 | AT16: 0 | AU16: 0 | AV16: 0 | AW16: 0 | AX16: 0 | AY16: 0 | AZ16: 0 | BA16: 0 | BB16: 0 | BC16: 0
A17: ZS\&POOL | B17: 1.0315954 | C17: 0.99374953 | D17: 1.0449213 | E17: 1.0089321 | F17: 0.98787214 | G17: 1.0107716 | H17: 0.97269388 | I17: 1.0001174 | J17: 0.95083297 | K17: 0.97717784 | L17: 0.92681421 | M17: 0.92415836 | N17: 0.99940268 | O17: 0.94453477 | P17: 1.0043743 | S17: ZS\&POOL | T17: 0 | U17: 0 | V17: 0 | W17: 0 | X17: 0 | Y17: 0 | Z17: 0 | AA17: 0 | AB17: 1 | AC17: 1 | AD17: 1 | AE17: 1 | AF17: 0 | AG17: 1 | AH17: 0 | AI17: 5 | AM17: ZS\&POOL | AN17: 0 | AO17: 0 | AP17: 0 | AQ17: 0 | AR17: 0 | AS17: 0 | AT17: 0 | AU17: 0 | AV17: 1 | AW17: 1 | AX17: 1 | AY17: 1 | AZ17: 0 | BA17: 1 | BB17: 0 | BC17: 5
A18: POOL | B18: 0.7830495 | C18: 1.0211689 | D18: 1.054431 | E18: 0.90066547 | F18: 1.0478299 | G18: 1.0357345 | H18: 1.0466834 | I18: 1.0464437 | J18: 1.0420107 | K18: 1.0117503 | L18: 1.0428232 | M18: 1.0312422 | N18: 0.981131 | O18: 0.64740687 | P18: 1.0118163 | S18: POOL | T18: 1 | U18: 0 | V18: 0 | W18: 1 | X18: 0 | Y18: 0 | Z18: 0 | AA18: 0 | AB18: 0 | AC18: 0 | AD18: 0 | AE18: 0 | AF18: 0 | AG18: 1 | AH18: 0 | AI18: 3 | AM18: POOL | AN18: 0 | AO18: 0 | AP18: 0 | AQ18: 1 | AR18: 0 | AS18: 0 | AT18: 0 | AU18: 0 | AV18: 0 | AW18: 0 | AX18: 0 | AY18: 0 | AZ18: 0 | BA18: 1 | BB18: 0 | BC18: 2
A19: ZSGL | B19: 0.92117121 | C19: 0.97972197 | D19: 0.97633801 | E19: 1.0569517 | F19: 1.0020848 | G19: 1.0002936 | H19: 1.0082307 | I19: 1.0241856 | J19: 1.0057154 | K19: 0.99142468 | L19: 1.0176705 | M19: 1.0133762 | N19: 0.97055887 | O19: 0.72090696 | P19: 0.99742991 | S19: ZSGL | T19: 1 | U19: 0 | V19: 0 | W19: 0 | X19: 0 | Y19: 0 | Z19: 0 | AA19: 0 | AB19: 0 | AC19: 0 | AD19: 0 | AE19: 0 | AF19: 0 | AG19: 1 | AH19: 0 | AI19: 2 | AM19: ZSGL | AN19: 0 | AO19: 0 | AP19: 0 | AQ19: 0 | AR19: 0 | AS19: 0 | AT19: 0 | AU19: 0 | AV19: 0 | AW19: 0 | AX19: 0 | AY19: 0 | AZ19: 0 | BA19: 1 | BB19: 0 | BC19: 1
A20: J | B20: 0.55852687 | C20: 1.3620584 | D20: 1.0499178 | E20: 0.27169925 | F20: 1.1474543 | G20: 1.0646595 | H20: 1.0246803 | I20: 1.3044094 | J20: 1.1607019 | K20: 1.1091569 | L20: 0.85391319 | M20: 0.99341685 | N20: 1.1628057 | O20: 0.6448243 | P20: 1.1080463 | S20: J | T20: 1 | U20: 0 | V20: 0 | W20: 1 | X20: 0 | Y20: 0 | Z20: 0 | AA20: 0 | AB20: 0 | AC20: 0 | AD20: 1 | AE20: 0 | AF20: 0 | AG20: 1 | AH20: 0 | AI20: 4 | AM20: J | AN20: 1 | AO20: 0 | AP20: 0 | AQ20: 1 | AR20: 0 | AS20: 0 | AT20: 0 | AU20: 0 | AV20: 0 | AW20: 0 | AX20: 0 | AY20: 0 | AZ20: 0 | BA20: 1 | BB20: 0 | BC20: 3
A21: BFCS | B21: 1.9640367 | C21: 1.0867682 | D21: 1.4182257 | E21: 2.4576641 | F21: 1.2207391 | G21: 1.3315208 | H21: 1.1467721 | I21: 1.104949 | J21: 1.5650378 | K21: 1.5437485 | L21: 0.9455798 | M21: 2.2552743 | N21: 1.0530826 | O21: 2.751303 | P21: 1.1230616 | S21: BFCS | T21: 0 | U21: 0 | V21: 0 | W21: 0 | X21: 0 | Y21: 0 | Z21: 0 | AA21: 0 | AB21: 0 | AC21: 0 | AD21: 1 | AE21: 0 | AF21: 0 | AG21: 0 | AH21: 0 | AI21: 1 | AM21: BFCS | AN21: 0 | AO21: 0 | AP21: 0 | AQ21: 0 | AR21: 0 | AS21: 0 | AT21: 0 | AU21: 0 | AV21: 0 | AW21: 0 | AX21: 1 | AY21: 0 | AZ21: 0 | BA21: 0 | BB21: 0 | BC21: 1
A22: SSSS | B22: 1.9671897 | C22: 1.1574747 | D22: 1.0755557 | E22: 1.0457632 | F22: 1.0092082 | G22: 0.96115439 | H22: 0.98775133 | I22: 1.1946985 | J22: 1.2138803 | K22: 1.1710577 | L22: 0.95358941 | M22: 1.3664005 | N22: 0.98045829 | O22: 1.6647869 | P22: 1.0016061 | S22: SSSS | T22: 0 | U22: 0 | V22: 0 | W22: 0 | X22: 0 | Y22: 0 | Z22: 0 | AA22: 0 | AB22: 0 | AC22: 0 | AD22: 0 | AE22: 0 | AF22: 0 | AG22: 0 | AH22: 0 | AI22: 0 | AM22: SSSS | AN22: 0 | AO22: 0 | AP22: 0 | AQ22: 0 | AR22: 0 | AS22: 0 | AT22: 0 | AU22: 0 | AV22: 0 | AW22: 0 | AX22: 0 | AY22: 0 | AZ22: 0 | BA22: 0 | BB22: 0 | BC22: 0
A23: BMS | B23: 1.3993366 | C23: 0.93729505 | D23: 1.1521989 | E23: 1.9966934 | F23: 0.97160399 | G23: 0.9532263 | H23: 1.3019446 | I23: 0.95528863 | J23: 0.94930346 | K23: 1.2376598 | L23: 0.88465847 | M23: 1.2775832 | N23: 0.99539995 | O23: 1.1713085 | P23: 1.0678855 | S23: BMS | T23: 0 | U23: 0 | V23: 0 | W23: 0 | X23: 0 | Y23: 0 | Z23: 0 | AA23: 0 | AB23: 0 | AC23: 0 | AD23: 0 | AE23: 0 | AF23: 0 | AG23: 0 | AH23: 0 | AI23: 0 | AM23: BMS | AN23: 0 | AO23: 0 | AP23: 0 | AQ23: 0 | AR23: 0 | AS23: 0 | AT23: 0 | AU23: 0 | AV23: 0 | AW23: 0 | AX23: 0 | AY23: 0 | AZ23: 0 | BA23: 0 | BB23: 0 | BC23: 0
A24: CC | B24: 1.975429 | C24: 1.1761024 | D24: 1.138558 | E24: 2.4821135 | F24: 1.1341531 | G24: 1.2093443 | H24: 1.1056022 | I24: 1.2437167 | J24: 1.1192675 | K24: 1.0805401 | L24: 0.95777188 | M24: 1.4241023 | N24: 1.9988338 | O24: 2.0938614 | P24: 1.088734 | S24: CC | T24: 0 | U24: 0 | V24: 0 | W24: 0 | X24: 0 | Y24: 0 | Z24: 0 | AA24: 0 | AB24: 0 | AC24: 0 | AD24: 0 | AE24: 0 | AF24: 0 | AG24: 0 | AH24: 0 | AI24: 0 | AM24: CC | AN24: 0 | AO24: 0 | AP24: 0 | AQ24: 0 | AR24: 0 | AS24: 0 | AT24: 0 | AU24: 0 | AV24: 0 | AW24: 0 | AX24: 0 | AY24: 0 | AZ24: 0 | BA24: 0 | BB24: 0 | BC24: 0
A25: r | S25: r | T25: 1 | U25: 3 | V25: 1 | W25: 2 | X25: 2 | Y25: 0 | Z25: 2 | AA25: 3 | AB25: 0 | AC25: 3 | AD25: 4 | AE25: 2 | AF25: 2 | AG25: 4 | AH25: 3 | AI25: 32 | AM25: r | AN25: 1 | AO25: 3 | AP25: 0 | AQ25: 2 | AR25: 2 | AS25: 0 | AT25: 2 | AU25: 3 | AV25: 0 | AW25: 3 | AX25: 4 | AY25: 2 | AZ25: 1 | BA25: 3 | BB25: 2 | BC25: 28
A26: ZS | B26: 1 | C26: 1 | D26: 1 | E26: 1 | F26: 1 | G26: 1 | H26: 1 | I26: 1 | J26: 1 | K26: 1 | L26: 1 | M26: 1 | N26: 1 | O26: 1 | P26: 1 | S26: ZS | T26: 0 | U26: 0 | V26: 0 | W26: 0 | X26: 0 | Y26: 0 | Z26: 0 | AA26: 0 | AB26: 0 | AC26: 0 | AD26: 0 | AE26: 0 | AF26: 0 | AG26: 0 | AH26: 0 | AI26: 0 | AM26: ZS | AN26: 0 | AO26: 0 | AP26: 0 | AQ26: 0 | AR26: 0 | AS26: 0 | AT26: 0 | AU26: 0 | AV26: 0 | AW26: 0 | AX26: 0 | AY26: 0 | AZ26: 0 | BA26: 0 | BB26: 0 | BC26: 0
A27: ZS\&POOL | B27: 1.102663 | C27: 1.0435117 | D27: 1.0292551 | E27: 1.0169792 | F27: 0.99125838 | G27: 0.99050105 | H27: 0.91398345 | I27: 1.0207689 | J27: 1.0355109 | K27: 0.96608576 | L27: 0.95241429 | M27: 0.92173726 | N27: 1.1461089 | O27: 0.99324026 | P27: 0.95187411 | S27: ZS\&POOL | T27: 0 | U27: 0 | V27: 0 | W27: 0 | X27: 0 | Y27: 0 | Z27: 1 | AA27: 0 | AB27: 0 | AC27: 1 | AD27: 1 | AE27: 1 | AF27: 0 | AG27: 0 | AH27: 1 | AI27: 5 | AM27: ZS\&POOL | AN27: 0 | AO27: 0 | AP27: 0 | AQ27: 0 | AR27: 0 | AS27: 0 | AT27: 1 | AU27: 0 | AV27: 0 | AW27: 1 | AX27: 1 | AY27: 1 | AZ27: 0 | BA27: 0 | BB27: 1 | BC27: 5
A28: POOL | B28: 0.87733208 | C28: 0.91189659 | D28: 1.0706026 | E28: 0.88360479 | F28: 1.0659786 | G28: 1.0673374 | H28: 0.98564657 | I28: 0.94972451 | J28: 1.0729279 | K28: 0.91178065 | L28: 0.94916182 | M28: 1.0028526 | N28: 1.0130356 | O28: 0.73759682 | P28: 0.97210535 | S28: POOL | T28: 0 | U28: 1 | V28: 0 | W28: 1 | X28: 0 | Y28: 0 | Z28: 0 | AA28: 1 | AB28: 0 | AC28: 1 | AD28: 1 | AE28: 0 | AF28: 0 | AG28: 1 | AH28: 1 | AI28: 7 | AM28: POOL | AN28: 0 | AO28: 1 | AP28: 0 | AQ28: 1 | AR28: 0 | AS28: 0 | AT28: 0 | AU28: 1 | AV28: 0 | AW28: 1 | AX28: 1 | AY28: 0 | AZ28: 0 | BA28: 1 | BB28: 0 | BC28: 6
A29: ZSGL | B29: 0.97453888 | C29: 0.9313719 | D29: 0.98774996 | E29: 1.0484376 | F29: 0.95651982 | G29: 1.0319629 | H29: 0.97342518 | I29: 0.89204059 | J29: 1.0329041 | K29: 0.96706678 | L29: 0.96506394 | M29: 1.006312 | N29: 0.92121441 | O29: 0.85356763 | P29: 1.0003727 | S29: ZSGL | T29: 0 | U29: 1 | V29: 0 | W29: 0 | X29: 1 | Y29: 0 | Z29: 1 | AA29: 1 | AB29: 0 | AC29: 0 | AD29: 1 | AE29: 0 | AF29: 1 | AG29: 1 | AH29: 0 | AI29: 7 | AM29: ZSGL | AN29: 0 | AO29: 1 | AP29: 0 | AQ29: 0 | AR29: 1 | AS29: 0 | AT29: 1 | AU29: 1 | AV29: 0 | AW29: 0 | AX29: 1 | AY29: 0 | AZ29: 1 | BA29: 1 | BB29: 0 | BC29: 7
A30: J | B30: 0.4753866 | C30: 0.83256317 | D30: 0.95920341 | E30: 0.16462728 | F30: 0.87878497 | G30: 1.01825 | H30: 0.9302469 | I30: 0.81795373 | J30: 0.98867713 | K30: 0.77015154 | L30: 0.78440302 | M30: 0.89046768 | N30: 0.71767352 | O30: 0.44203164 | P30: 0.80754702 | S30: J | T30: 1 | U30: 1 | V30: 1 | W30: 1 | X30: 1 | Y30: 0 | Z30: 0 | AA30: 1 | AB30: 0 | AC30: 1 | AD30: 1 | AE30: 1 | AF30: 1 | AG30: 1 | AH30: 1 | AI30: 12 | AM30: J | AN30: 1 | AO30: 1 | AP30: 0 | AQ30: 1 | AR30: 1 | AT30: 0 | AU30: 1 | AV30: 0 | AW30: 1 | AX30: 1 | AY30: 1 | AZ30: 0 | BA30: 1 | BB30: 1 | BC30: 10
A31: BFCS | B31: 1.7520502 | C31: 1.9085691 | D31: 1.6613537 | E31: 2.2796489 | F31: 2.754995 | G31: 2.3841217 | H31: 2.8683526 | I31: 1.7359081 | J31: 3.2064379 | K31: 3.0450672 | L31: 1.148756 | M31: 2.6712533 | N31: 0.99357569 | O31: 3.3270382 | P31: 2.0786148 | S31: BFCS | T31: 0 | U31: 0 | V31: 0 | W31: 0 | X31: 0 | Y31: 0 | Z31: 0 | AA31: 0 | AB31: 0 | AC31: 0 | AD31: 0 | AE31: 0 | AF31: 0 | AG31: 0 | AH31: 0 | AI31: 0 | AM31: BFCS | AN31: 0 | AO31: 0 | AP31: 0 | AQ31: 0 | AR31: 0 | AS31: 0 | AT31: 0 | AU31: 0 | AV31: 0 | AW31: 0 | AX31: 0 | AY31: 0 | AZ31: 0 | BA31: 0 | BB31: 0 | BC31: 0
A32: SSSS | B32: 1.2825821 | C32: 1.1554732 | D32: 1.7633726 | E32: 2.0154487 | F32: 1.2292012 | G32: 1.1194978 | H32: 0.95041986 | I32: 1.1031005 | J32: 1.4671062 | K32: 1.1478664 | L32: 0.9246687 | M32: 1.7300149 | N32: 1.5945643 | O32: 0.84434689 | P32: 1.1332688 | S32: SSSS | T32: 0 | U32: 0 | V32: 0 | W32: 0 | X32: 0 | Y32: 0 | Z32: 0 | AA32: 0 | AB32: 0 | AC32: 0 | AD32: 0 | AE32: 0 | AF32: 0 | AG32: 1 | AH32: 0 | AI32: 1 | AM32: SSSS | AN32: 0 | AO32: 0 | AP32: 0 | AQ32: 0 | AR32: 0 | AS32: 0 | AT32: 0 | AU32: 0 | AV32: 0 | AW32: 0 | AX32: 0 | AY32: 0 | AZ32: 0 | BA32: 0 | BB32: 0 | BC32: 0
A33: BMS | B33: 1.3460489 | C33: 1.375177 | D33: 1.2913848 | E33: 2.0441157 | F33: 1.5520672 | G33: 1.4615424 | H33: 1.6744738 | I33: 1.2918631 | J33: 1.9328869 | K33: 1.7058766 | L33: 1.0864967 | M33: 1.761294 | N33: 1.1494044 | O33: 1.6440507 | P33: 1.2608077 | S33: BMS | T33: 0 | U33: 0 | V33: 0 | W33: 0 | X33: 0 | Y33: 0 | Z33: 0 | AA33: 0 | AB33: 0 | AC33: 0 | AD33: 0 | AE33: 0 | AF33: 0 | AG33: 0 | AH33: 0 | AI33: 0 | AM33: BMS | AN33: 0 | AO33: 0 | AP33: 0 | AQ33: 0 | AR33: 0 | AS33: 0 | AT33: 0 | AU33: 0 | AV33: 0 | AW33: 0 | AX33: 0 | AY33: 0 | AZ33: 0 | BA33: 0 | BB33: 0 | BC33: 0
A34: CC | B34: 1.8518544 | C34: 2.1896108 | D34: 1.8858996 | E34: 2.3417618 | F34: 2.3111592 | G34: 1.6776759 | H34: 2.6148879 | I34: 2.0158326 | J34: 3.2469756 | K34: 2.3135901 | L34: 1.1245182 | M34: 2.1692789 | N34: 3.5379766 | O34: 2.3993243 | P34: 1.8038483 | S34: CC | T34: 0 | U34: 0 | V34: 0 | W34: 0 | X34: 0 | Y34: 0 | Z34: 0 | AA34: 0 | AB34: 0 | AC34: 0 | AD34: 0 | AE34: 0 | AF34: 0 | AG34: 0 | AH34: 0 | AI34: 0 | AM34: CC | AN34: 0 | AO34: 0 | AP34: 0 | AQ34: 0 | AR34: 0 | AS34: 0 | AT34: 0 | AU34: 0 | AV34: 0 | AW34: 0 | AX34: 0 | AY34: 0 | AZ34: 0 | BA34: 0 | BB34: 0 | BC34: 0
S35: Grand Total | T35: 6 | U35: 3 | V35: 4 | W35: 5 | X35: 5 | Y35: 0 | Z35: 2 | AA35: 7 | AB35: 2 | AC35: 4 | AD35: 7 | AE35: 6 | AF35: 4 | AG35: 8 | AH35: 4 | AI35: 67 | AM35: Grand Total | AN35: 4 | AO35: 3 | AP35: 2 | AQ35: 5 | AR35: 5 | AS35: 0 | AT35: 2 | AU35: 3 | AV35: 2 | AW35: 4 | AX35: 6 | AY35: 5 | AZ35: 2 | BA35: 7 | BB35: 3 | BC35: 53

Sheet rmsfe_Pivot_T8
S1: 0.1 | AM1: 0.05
A3: Sum of T_8 | B3: Column Labels | S3: Sum of T_8 | T3: Column Labels | AM3: Sum of T_8 | AN3: Column Labels
A4: Row Labels | B4: AG | C4: AT | D4: AU | E4: BR | F4: CA | G4: CH | H4: CN | I4: DE | J4: FR | K4: GB | L4: IN | M4: IT | N4: JP | O4: MX | P4: US | S4: Row Labels | T4: AG | U4: AT | V4: AU | W4: BR | X4: CA | Y4: CH | Z4: CN | AA4: DE | AB4: FR | AC4: GB | AD4: IN | AE4: IT | AF4: JP | AG4: MX | AH4: US | AI4: Grand Total | AM4: Row Labels | AN4: AG | AO4: AT | AP4: AU | AQ4: BR | AR4: CA | AS4: CH | AT4: CN | AU4: DE | AV4: FR | AW4: GB | AX4: IN | AY4: IT | AZ4: JP | BA4: MX | BB4: US | BC4: Grand Total
A5: y | S5: y | T5: 0 | U5: 1 | V5: 2 | W5: 0 | X5: 3 | Y5: 1 | Z5: 0 | AA5: 1 | AB5: 0 | AC5: 2 | AD5: 0 | AE5: 0 | AF5: 0 | AG5: 0 | AH5: 0 | AI5: 10 | AM5: y | AN5: 0 | AO5: 1 | AP5: 2 | AQ5: 0 | AR5: 3 | AS5: 0 | AT5: 0 | AU5: 0 | AV5: 0 | AW5: 0 | AX5: 0 | AY5: 0 | AZ5: 0 | BA5: 0 | BB5: 0 | BC5: 6
A6: ZS | B6: 1 | C6: 1 | D6: 1 | E6: 1 | F6: 1 | G6: 1 | H6: 1 | I6: 1 | J6: 1 | K6: 1 | L6: 1 | M6: 1 | N6: 1 | O6: 1 | P6: 1 | S6: ZS | T6: 0 | U6: 0 | V6: 0 | W6: 0 | X6: 0 | Y6: 0 | Z6: 0 | AA6: 0 | AB6: 0 | AC6: 0 | AD6: 0 | AE6: 0 | AF6: 0 | AG6: 0 | AH6: 0 | AI6: 0 | AM6: ZS | AN6: 0 | AO6: 0 | AP6: 0 | AQ6: 0 | AR6: 0 | AS6: 0 | AT6: 0 | AU6: 0 | AV6: 0 | AW6: 0 | AX6: 0 | AY6: 0 | AZ6: 0 | BA6: 0 | BB6: 0 | BC6: 0
A7: ZS\&POOL | B7: 0.99650451 | C7: 0.9965887 | D7: 0.97594481 | E7: 1.0001416 | F7: 0.96183608 | G7: 0.99724169 | H7: 0.99092346 | I7: 0.98557724 | J7: 0.99888551 | K7: 0.99285212 | L7: 1.000065 | M7: 1.0224067 | N7: 1.0208234 | O7: 1.0017488 | P7: 1.0055898 | S7: ZS\&POOL | T7: 0 | U7: 1 | V7: 1 | W7: 0 | X7: 1 | Y7: 0 | Z7: 0 | AA7: 1 | AB7: 0 | AC7: 0 | AD7: 0 | AE7: 0 | AF7: 0 | AG7: 0 | AH7: 0 | AI7: 4 | AM7: ZS\&POOL | AN7: 0 | AO7: 1 | AP7: 1 | AQ7: 0 | AR7: 1 | AS7: 0 | AT7: 0 | AU7: 0 | AV7: 0 | AW7: 0 | AX7: 0 | AY7: 0 | AZ7: 0 | BA7: 0 | BB7: 0 | BC7: 3
A8: POOL | B8: 1.0045067 | C8: 1.0004102 | D8: 1.0002856 | E8: 1.001563 | F8: 0.99685264 | G8: 1.012666 | H8: 1.0308338 | I8: 0.99557677 | J8: 1.0274343 | K8: 0.98946357 | L8: 0.99461084 | M8: 0.97183244 | N8: 1.0014631 | O8: 1.0011536 | P8: 0.99885125 | S8: POOL | T8: 0 | U8: 0 | V8: 0 | W8: 0 | X8: 0 | Y8: 0 | Z8: 0 | AA8: 0 | AB8: 0 | AC8: 0 | AD8: 0 | AE8: 0 | AF8: 0 | AG8: 0 | AH8: 0 | AI8: 0 | AM8: POOL | AN8: 0 | AO8: 0 | AP8: 0 | AQ8: 0 | AR8: 0 | AS8: 0 | AT8: 0 | AU8: 0 | AV8: 0 | AW8: 0 | AX8: 0 | AY8: 0 | AZ8: 0 | BA8: 0 | BB8: 0 | BC8: 0
A9: ZSGL | B9: 1.0038453 | C9: 1.001847 | D9: 1.0110983 | E9: 0.99984953 | F9: 1.0194376 | G9: 1.0031116 | H9: 1.0153524 | I9: 0.98921433 | J9: 1.0114863 | K9: 0.99698361 | L9: 0.99990925 | M9: 1.0003681 | N9: 0.99680366 | O9: 1.0081126 | P9: 0.99814935 | S9: ZSGL | T9: 0 | U9: 0 | V9: 0 | W9: 0 | X9: 0 | Y9: 0 | Z9: 0 | AA9: 0 | AB9: 0 | AC9: 1 | AD9: 0 | AE9: 0 | AF9: 0 | AG9: 0 | AH9: 0 | AI9: 1 | AM9: ZSGL | AN9: 0 | AO9: 0 | AP9: 0 | AQ9: 0 | AR9: 0 | AS9: 0 | AT9: 0 | AU9: 0 | AV9: 0 | AW9: 0 | AX9: 0 | AY9: 0 | AZ9: 0 | BA9: 0 | BB9: 0 | BC9: 0
A10: J | B10: 0.96325392 | C10: 1.0033534 | D10: 0.95712435 | E10: 0.9944903 | F10: 0.94220171 | G10: 0.98770836 | H10: 1.0417138 | I10: 0.99060854 | J10: 0.9993138 | K10: 1.0043974 | L10: 1.0573743 | M10: 1.0018282 | N10: 1.0296545 | O10: 0.99574009 | P10: 1.0213733 | S10: J | T10: 0 | U10: 0 | V10: 1 | W10: 0 | X10: 1 | Y10: 0 | Z10: 0 | AA10: 0 | AB10: 0 | AC10: 0 | AD10: 0 | AE10: 0 | AF10: 0 | AG10: 0 | AH10: 0 | AI10: 2 | AM10: J | AN10: 0 | AO10: 0 | AP10: 1 | AQ10: 0 | AR10: 1 | AS10: 0 | AT10: 0 | AU10: 0 | AV10: 0 | AW10: 0 | AX10: 0 | AY10: 0 | AZ10: 0 | BA10: 0 | BB10: 0 | BC10: 2
A11: BFCS | B11: 1.0064287 | C11: 1.0329756 | D11: 0.96633918 | E11: 1.0419574 | F11: 0.93007857 | G11: 0.98479896 | H11: 1.0014319 | I11: 1.0023074 | J11: 0.99236278 | K11: 0.96764 | L11: 1.0298167 | M11: 0.99645139 | N11: 1.0128732 | O11: 1.0411302 | P11: 1.0105479 | S11: BFCS | T11: 0 | U11: 0 | V11: 0 | W11: 0 | X11: 1 | Y11: 1 | Z11: 0 | AA11: 0 | AB11: 0 | AC11: 1 | AD11: 0 | AE11: 0 | AF11: 0 | AG11: 0 | AH11: 0 | AI11: 3 | AM11: BFCS | AN11: 0 | AO11: 0 | AP11: 0 | AQ11: 0 | AR11: 1 | AS11: 0 | AT11: 0 | AU11: 0 | AV11: 0 | AW11: 0 | AX11: 0 | AY11: 0 | AZ11: 0 | BA11: 0 | BB11: 0 | BC11: 1
A12: SSSS | B12: 1.1998377 | C12: 1.0254115 | D12: 1.2644667 | E12: 8.3389601 | F12: 1.1173224 | G12: 1.0087192 | H12: 1.0964027 | I12: 0.98164936 | J12: 1.139625 | K12: 1.1063933 | L12: 1.1077021 | M12: 1.3833122 | N12: 1.0337158 | O12: 2.1605027 | P12: 1.0322412 | S12: SSSS | T12: 0 | U12: 0 | V12: 0 | W12: 0 | X12: 0 | Y12: 0 | Z12: 0 | AA12: 0 | AB12: 0 | AC12: 0 | AD12: 0 | AE12: 0 | AF12: 0 | AG12: 0 | AH12: 0 | AI12: 0 | AM12: SSSS | AN12: 0 | AO12: 0 | AP12: 0 | AQ12: 0 | AR12: 0 | AS12: 0 | AT12: 0 | AU12: 0 | AV12: 0 | AW12: 0 | AX12: 0 | AY12: 0 | AZ12: 0 | BA12: 0 | BB12: 0 | BC12: 0
A13: BMS | B13: 1.1558648 | C13: 1.0171564 | D13: 1.266444 | E13: 1.1696755 | F13: 1.1028381 | G13: 1.0652167 | H13: 1.0802219 | I13: 1.0009821 | J13: 1.0824036 | K13: 1.0628917 | L13: 1.022763 | M13: 1.030816 | N13: 1.0091897 | O13: 1.0308002 | P13: 1.0840516 | S13: BMS | T13: 0 | U13: 0 | V13: 0 | W13: 0 | X13: 0 | Y13: 0 | Z13: 0 | AA13: 0 | AB13: 0 | AC13: 0 | AD13: 0 | AE13: 0 | AF13: 0 | AG13: 0 | AH13: 0 | AI13: 0 | AM13: BMS | AN13: 0 | AO13: 0 | AP13: 0 | AQ13: 0 | AR13: 0 | AS13: 0 | AT13: 0 | AU13: 0 | AV13: 0 | AW13: 0 | AX13: 0 | AY13: 0 | AZ13: 0 | BA13: 0 | BB13: 0 | BC13: 0
A14: CC | B14: 1.5547156 | C14: 1.9638803 | D14: 3.2163074 | E14: 2.1653891 | F14: 2.803222 | G14: 2.0566088 | H14: 1.664013 | I14: 2.1636318 | J14: 3.1197196 | K14: 2.2245651 | L14: 1.632705 | M14: 2.7462996 | N14: 2.0107102 | O14: 2.2474687 | P14: 2.8351847 | S14: CC | T14: 0 | U14: 0 | V14: 0 | W14: 0 | X14: 0 | Y14: 0 | Z14: 0 | AA14: 0 | AB14: 0 | AC14: 0 | AD14: 0 | AE14: 0 | AF14: 0 | AG14: 0 | AH14: 0 | AI14: 0 | AM14: CC | AN14: 0 | AO14: 0 | AP14: 0 | AQ14: 0 | AR14: 0 | AS14: 0 | AT14: 0 | AU14: 0 | AV14: 0 | AW14: 0 | AX14: 0 | AY14: 0 | AZ14: 0 | BA14: 0 | BB14: 0 | BC14: 0
A15: Dp | S15: Dp | T15: 1 | U15: 0 | V15: 1 | W15: 3 | X15: 1 | Y15: 2 | Z15: 1 | AA15: 0 | AB15: 1 | AC15: 1 | AD15: 0 | AE15: 1 | AF15: 1 | AG15: 5 | AH15: 0 | AI15: 18 | AM15: Dp | AN15: 1 | AO15: 0 | AP15: 0 | AQ15: 3 | AR15: 1 | AS15: 1 | AT15: 0 | AU15: 0 | AV15: 1 | AW15: 0 | AX15: 0 | AY15: 1 | AZ15: 0 | BA15: 5 | BB15: 0 | BC15: 13
A16: ZS | B16: 1 | C16: 1 | D16: 1 | E16: 1 | F16: 1 | G16: 1 | H16: 1 | I16: 1 | J16: 1 | K16: 1 | L16: 1 | M16: 1 | N16: 1 | O16: 1 | P16: 1 | S16: ZS | T16: 0 | U16: 0 | V16: 0 | W16: 0 | X16: 0 | Y16: 0 | Z16: 0 | AA16: 0 | AB16: 0 | AC16: 0 | AD16: 0 | AE16: 0 | AF16: 0 | AG16: 0 | AH16: 0 | AI16: 0 | AM16: ZS | AN16: 0 | AO16: 0 | AP16: 0 | AQ16: 0 | AR16: 0 | AS16: 0 | AT16: 0 | AU16: 0 | AV16: 0 | AW16: 0 | AX16: 0 | AY16: 0 | AZ16: 0 | BA16: 0 | BB16: 0 | BC16: 0
A17: ZS\&POOL | B17: 1.1369912 | C17: 0.99279395 | D17: 1.0798028 | E17: 1.0282935 | F17: 0.99697366 | G17: 1.035245 | H17: 0.98893526 | I17: 0.98252264 | J17: 0.92143156 | K17: 0.98372531 | L17: 1.0015572 | M17: 0.88611484 | N17: 1.0111983 | O17: 0.9693292 | P17: 1.0009164 | S17: ZS\&POOL | T17: 0 | U17: 0 | V17: 0 | W17: 0 | X17: 0 | Y17: 0 | Z17: 0 | AA17: 0 | AB17: 1 | AC17: 0 | AD17: 0 | AE17: 1 | AF17: 0 | AG17: 1 | AH17: 0 | AI17: 3 | AM17: ZS\&POOL | AN17: 0 | AO17: 0 | AP17: 0 | AQ17: 0 | AR17: 0 | AS17: 0 | AT17: 0 | AU17: 0 | AV17: 1 | AW17: 0 | AX17: 0 | AY17: 1 | AZ17: 0 | BA17: 1 | BB17: 0 | BC17: 3
A18: POOL | B18: 0.91841015 | C18: 0.99635874 | D18: 1.0985005 | E18: 0.8937097 | F18: 1.0401573 | G18: 1.0725025 | H18: 1.0294053 | I18: 1.041306 | J18: 1.0788722 | K18: 1.0247124 | L18: 1.0475395 | M18: 1.1018709 | N18: 0.97812516 | O18: 0.66588454 | P18: 1.0157747 | S18: POOL | T18: 0 | U18: 0 | V18: 0 | W18: 1 | X18: 0 | Y18: 0 | Z18: 0 | AA18: 0 | AB18: 0 | AC18: 0 | AD18: 0 | AE18: 0 | AF18: 0 | AG18: 1 | AH18: 0 | AI18: 2 | AM18: POOL | AN18: 0 | AO18: 0 | AP18: 0 | AQ18: 1 | AR18: 0 | AS18: 0 | AT18: 0 | AU18: 0 | AV18: 0 | AW18: 0 | AX18: 0 | AY18: 0 | AZ18: 0 | BA18: 1 | BB18: 0 | BC18: 2
A19: ZSGL | B19: 0.99348833 | C19: 0.97799817 | D19: 0.96818962 | E19: 1.0561816 | F19: 0.99008843 | G19: 1.0140985 | H19: 0.99818031 | I19: 0.99794031 | J19: 1.0141055 | K19: 0.96178347 | L19: 1.0029319 | M19: 1.0409255 | N19: 0.96943176 | O19: 0.7336857 | P19: 0.99104447 | S19: ZSGL | T19: 0 | U19: 0 | V19: 1 | W19: 0 | X19: 0 | Y19: 0 | Z19: 0 | AA19: 0 | AB19: 0 | AC19: 1 | AD19: 0 | AE19: 0 | AF19: 1 | AG19: 1 | AH19: 0 | AI19: 4 | AM19: ZSGL | AN19: 0 | AO19: 0 | AP19: 0 | AQ19: 0 | AR19: 0 | AS19: 0 | AT19: 0 | AU19: 0 | AV19: 0 | AW19: 0 | AX19: 0 | AY19: 0 | AZ19: 0 | BA19: 1 | BB19: 0 | BC19: 1
A20: J | B20: 0.41266031 | C20: 1.4157086 | D20: 0.98733187 | E20: 0.23977369 | F20: 1.1792375 | G20: 0.98977609 | H20: 1.0338256 | I20: 1.3961462 | J20: 1.1234205 | K20: 1.0889581 | L20: 0.94085122 | M20: 0.8482535 | N20: 1.2131448 | O20: 0.62402965 | P20: 1.1204806 | S20: J | T20: 1 | U20: 0 | V20: 0 | W20: 1 | X20: 0 | Y20: 0 | Z20: 0 | AA20: 0 | AB20: 0 | AC20: 0 | AD20: 0 | AE20: 0 | AF20: 0 | AG20: 1 | AH20: 0 | AI20: 3 | AM20: J | AN20: 1 | AO20: 0 | AP20: 0 | AQ20: 1 | AR20: 0 | AS20: 0 | AT20: 0 | AU20: 0 | AV20: 0 | AW20: 0 | AX20: 0 | AY20: 0 | AZ20: 0 | BA20: 1 | BB20: 0 | BC20: 3
A21: BFCS | B21: 1.5336527 | C21: 1.0777855 | D21: 1.4144068 | E21: 1.623161 | F21: 1.1995146 | G21: 1.2685672 | H21: 1.169078 | I21: 1.0642778 | J21: 1.4710189 | K21: 1.3550615 | L21: 0.99287734 | M21: 1.7872912 | N21: 1.0395061 | O21: 1.8554668 | P21: 1.0798802 | S21: BFCS | T21: 0 | U21: 0 | V21: 0 | W21: 0 | X21: 0 | Y21: 0 | Z21: 0 | AA21: 0 | AB21: 0 | AC21: 0 | AD21: 0 | AE21: 0 | AF21: 0 | AG21: 0 | AH21: 0 | AI21: 0 | AM21: BFCS | AN21: 0 | AO21: 0 | AP21: 0 | AQ21: 0 | AR21: 0 | AS21: 0 | AT21: 0 | AU21: 0 | AV21: 0 | AW21: 0 | AX21: 0 | AY21: 0 | AZ21: 0 | BA21: 0 | BB21: 0 | BC21: 0
A22: SSSS | B22: 1.4549247 | C22: 1.1401856 | D22: 1.0867619 | E22: 0.68926304 | F22: 1.0044426 | G22: 0.92858474 | H22: 0.88187104 | I22: 1.1005956 | J22: 1.1757511 | K22: 1.008995 | L22: 1.0379005 | M22: 1.1235255 | N22: 1.0030907 | O22: 1.1305882 | P22: 0.98284613 | S22: SSSS | T22: 0 | U22: 0 | V22: 0 | W22: 1 | X22: 0 | Y22: 1 | Z22: 1 | AA22: 0 | AB22: 0 | AC22: 0 | AD22: 0 | AE22: 0 | AF22: 0 | AG22: 0 | AH22: 0 | AI22: 3 | AM22: SSSS | AN22: 0 | AO22: 0 | AP22: 0 | AQ22: 1 | AR22: 0 | AS22: 0 | AT22: 0 | AU22: 0 | AV22: 0 | AW22: 0 | AX22: 0 | AY22: 0 | AZ22: 0 | BA22: 0 | BB22: 0 | BC22: 1
A23: BMS | B23: 1.081114 | C23: 0.9459587 | D23: 1.1313075 | E23: 1.3173937 | F23: 0.93678935 | G23: 0.92639139 | H23: 1.2886965 | I23: 0.95672869 | J23: 0.89752852 | K23: 1.1085385 | L23: 0.93994284 | M23: 1.0252288 | N23: 0.96025086 | O23: 0.80203132 | P23: 1.0325199 | S23: BMS | T23: 0 | U23: 0 | V23: 0 | W23: 0 | X23: 1 | Y23: 1 | Z23: 0 | AA23: 0 | AB23: 0 | AC23: 0 | AD23: 0 | AE23: 0 | AF23: 0 | AG23: 1 | AH23: 0 | AI23: 3 | AM23: BMS | AN23: 0 | AO23: 0 | AP23: 0 | AQ23: 0 | AR23: 1 | AS23: 1 | AT23: 0 | AU23: 0 | AV23: 0 | AW23: 0 | AX23: 0 | AY23: 0 | AZ23: 0 | BA23: 1 | BB23: 0 | BC23: 3
A24: CC | B24: 1.5520472 | C24: 1.2469231 | D24: 1.1480992 | E24: 1.6336444 | F24: 1.2778162 | G24: 1.1550701 | H24: 1.1514312 | I24: 1.3333348 | J24: 1.1051806 | K24: 1.0203751 | L24: 0.98842525 | M24: 1.2168306 | N24: 2.0914854 | O24: 1.4202655 | P24: 1.1136501 | S24: CC | T24: 0 | U24: 0 | V24: 0 | W24: 0 | X24: 0 | Y24: 0 | Z24: 0 | AA24: 0 | AB24: 0 | AC24: 0 | AD24: 0 | AE24: 0 | AF24: 0 | AG24: 0 | AH24: 0 | AI24: 0 | AM24: CC | AN24: 0 | AO24: 0 | AP24: 0 | AQ24: 0 | AR24: 0 | AS24: 0 | AT24: 0 | AU24: 0 | AV24: 0 | AW24: 0 | AX24: 0 | AY24: 0 | AZ24: 0 | BA24: 0 | BB24: 0 | BC24: 0
A25: r | S25: r | T25: 1 | U25: 5 | V25: 2 | W25: 2 | X25: 3 | Y25: 1 | Z25: 4 | AA25: 5 | AB25: 1 | AC25: 5 | AD25: 2 | AE25: 2 | AF25: 5 | AG25: 4 | AH25: 4 | AI25: 46 | AM25: r | AN25: 1 | AO25: 5 | AP25: 1 | AQ25: 2 | AR25: 3 | AS25: 0 | AT25: 3 | AU25: 5 | AV25: 1 | AW25: 5 | AX25: 1 | AY25: 2 | AZ25: 5 | BA25: 4 | BB25: 4 | BC25: 42
A26: ZS | B26: 1 | C26: 1 | D26: 1 | E26: 1 | F26: 1 | G26: 1 | H26: 1 | I26: 1 | J26: 1 | K26: 1 | L26: 1 | M26: 1 | N26: 1 | O26: 1 | P26: 1 | S26: ZS | T26: 0 | U26: 0 | V26: 0 | W26: 0 | X26: 0 | Y26: 0 | Z26: 0 | AA26: 0 | AB26: 0 | AC26: 0 | AD26: 0 | AE26: 0 | AF26: 0 | AG26: 0 | AH26: 0 | AI26: 0 | AM26: ZS | AN26: 0 | AO26: 0 | AP26: 0 | AQ26: 0 | AR26: 0 | AS26: 0 | AT26: 0 | AU26: 0 | AV26: 0 | AW26: 0 | AX26: 0 | AY26: 0 | AZ26: 0 | BA26: 0 | BB26: 0 | BC26: 0
A27: ZS\&POOL | B27: 1.1202016 | C27: 1.0137548 | D27: 1.0203724 | E27: 1.0354988 | F27: 0.99140486 | G27: 0.98382161 | H27: 0.89824094 | I27: 0.99538461 | J27: 1.0617261 | K27: 0.98146614 | L27: 0.96126972 | M27: 0.91543635 | N27: 1.1973886 | O27: 1.0309577 | P27: 0.95669447 | S27: ZS\&POOL | T27: 0 | U27: 0 | V27: 0 | W27: 0 | X27: 0 | Y27: 1 | Z27: 1 | AA27: 0 | AB27: 0 | AC27: 1 | AD27: 0 | AE27: 1 | AF27: 0 | AG27: 0 | AH27: 1 | AI27: 5 | AM27: ZS\&POOL | AN27: 0 | AO27: 0 | AP27: 0 | AQ27: 0 | AR27: 0 | AS27: 0 | AT27: 1 | AU27: 0 | AV27: 0 | AW27: 1 | AX27: 0 | AY27: 1 | AZ27: 0 | BA27: 0 | BB27: 1 | BC27: 4
A28: POOL | B28: 0.94125201 | C28: 0.90020371 | D28: 1.1079202 | E28: 0.89658693 | F28: 1.0426675 | G28: 1.1398744 | H28: 0.97216358 | I28: 0.92406022 | J28: 1.1526297 | K28: 0.92444026 | L28: 0.99103314 | M28: 1.0181829 | N28: 0.94954923 | O28: 0.78176723 | P28: 0.97073841 | S28: POOL | T28: 0 | U28: 1 | V28: 0 | W28: 1 | X28: 0 | Y28: 0 | Z28: 0 | AA28: 1 | AB28: 0 | AC28: 1 | AD28: 0 | AE28: 0 | AF28: 1 | AG28: 1 | AH28: 0 | AI28: 6 | AM28: POOL | AN28: 0 | AO28: 1 | AP28: 0 | AQ28: 1 | AR28: 0 | AS28: 0 | AT28: 0 | AU28: 1 | AV28: 0 | AW28: 1 | AX28: 0 | AY28: 0 | AZ28: 1 | BA28: 1 | BB28: 0 | BC28: 6
A29: ZSGL | B29: 0.98948933 | C29: 0.93372064 | D29: 0.97630316 | E29: 1.0528781 | F29: 0.96011 | G29: 1.0592489 | H29: 0.96144716 | I29: 0.88188736 | J29: 1.0500768 | K29: 0.93665414 | L29: 0.9719284 | M29: 1.0002506 | N29: 0.93222314 | O29: 0.85286063 | P29: 0.98963524 | S29: ZSGL | T29: 0 | U29: 1 | V29: 1 | W29: 0 | X29: 1 | Y29: 0 | Z29: 1 | AA29: 1 | AB29: 0 | AC29: 1 | AD29: 1 | AE29: 0 | AF29: 1 | AG29: 1 | AH29: 0 | AI29: 9 | AM29: ZSGL | AN29: 0 | AO29: 1 | AP29: 0 | AQ29: 0 | AR29: 1 | AS29: 0 | AT29: 1 | AU29: 1 | AV29: 0 | AW29: 1 | AX29: 1 | AY29: 0 | AZ29: 1 | BA29: 1 | BB29: 0 | BC29: 8
A30: J | B30: 0.41437382 | C30: 0.74960853 | D30: 0.87796796 | E30: 0.14802812 | F30: 0.82892828 | G30: 0.97477591 | H30: 0.80924776 | I30: 0.7331859 | J30: 0.94489712 | K30: 0.72914705 | L30: 0.77630825 | M30: 0.82003303 | N30: 0.55062514 | O30: 0.46111858 | P30: 0.79305943 | S30: J | T30: 1 | U30: 1 | V30: 1 | W30: 1 | X30: 1 | Y30: 0 | Z30: 1 | AA30: 1 | AB30: 1 | AC30: 1 | AD30: 0 | AE30: 1 | AF30: 1 | AG30: 1 | AH30: 1 | AI30: 13 | AM30: J | AN30: 1 | AO30: 1 | AP30: 1 | AQ30: 1 | AR30: 1 | AT30: 0 | AU30: 1 | AV30: 1 | AW30: 1 | AX30: 0 | AY30: 1 | AZ30: 1 | BA30: 1 | BB30: 1 | BC30: 12
A31: BFCS | B31: 1.3010556 | C31: 1.194141 | D31: 1.1792708 | E31: 1.5592305 | F31: 1.6989405 | G31: 1.6305186 | H31: 1.7003472 | I31: 1.0756853 | J31: 2.000436 | K31: 1.8696982 | L31: 0.98184876 | M31: 1.6172695 | N31: 0.61376902 | O31: 2.0921694 | P31: 1.3518074 | S31: BFCS | T31: 0 | U31: 0 | V31: 0 | W31: 0 | X31: 0 | Y31: 0 | Z31: 0 | AA31: 0 | AB31: 0 | AC31: 0 | AD31: 0 | AE31: 0 | AF31: 1 | AG31: 0 | AH31: 0 | AI31: 1 | AM31: BFCS | AN31: 0 | AO31: 0 | AP31: 0 | AQ31: 0 | AR31: 0 | AS31: 0 | AT31: 0 | AU31: 0 | AV31: 0 | AW31: 0 | AX31: 0 | AY31: 0 | AZ31: 1 | BA31: 0 | BB31: 0 | BC31: 1
A32: SSSS | B32: 0.8980071 | C32: 0.81028505 | D32: 1.2845512 | E32: 1.3384034 | F32: 0.8723982 | G32: 0.97824167 | H32: 0.6660159 | I32: 0.7728958 | J32: 1.0653332 | K32: 0.81601496 | L32: 0.97921538 | M32: 1.1237826 | N32: 0.95532372 | O32: 0.54042259 | P32: 0.88612219 | S32: SSSS | T32: 0 | U32: 1 | V32: 0 | W32: 0 | X32: 1 | Y32: 0 | Z32: 1 | AA32: 1 | AB32: 0 | AC32: 1 | AD32: 0 | AE32: 0 | AF32: 0 | AG32: 1 | AH32: 1 | AI32: 7 | AM32: SSSS | AN32: 0 | AO32: 1 | AP32: 0 | AQ32: 0 | AR32: 1 | AS32: 0 | AT32: 1 | AU32: 1 | AV32: 0 | AW32: 1 | AX32: 0 | AY32: 0 | AZ32: 0 | BA32: 1 | BB32: 1 | BC32: 7
A33: BMS | B33: 1.0098517 | C33: 0.88223593 | D33: 0.92050754 | E33: 1.3961559 | F33: 1.0171913 | G33: 1.0752707 | H33: 1.020365 | I33: 0.81622683 | J33: 1.2506957 | K33: 1.1146873 | L33: 0.99575043 | M33: 1.1109597 | N33: 0.68681584 | O33: 1.0915728 | P33: 0.89776783 | S33: BMS | T33: 0 | U33: 1 | V33: 0 | W33: 0 | X33: 0 | Y33: 0 | Z33: 0 | AA33: 1 | AB33: 0 | AC33: 0 | AD33: 0 | AE33: 0 | AF33: 1 | AG33: 0 | AH33: 1 | AI33: 4 | AM33: BMS | AN33: 0 | AO33: 1 | AP33: 0 | AQ33: 0 | AR33: 0 | AS33: 0 | AT33: 0 | AU33: 1 | AV33: 0 | AW33: 0 | AX33: 0 | AY33: 0 | AZ33: 1 | BA33: 0 | BB33: 1 | BC33: 4
A34: CC | B34: 1.3812907 | C34: 1.3288015 | D34: 1.3622478 | E34: 1.5904166 | F34: 1.4701297 | G34: 1.2317361 | H34: 1.5894903 | I34: 1.2189734 | J34: 2.0165778 | K34: 1.4524472 | L34: 0.91976998 | M34: 1.3682717 | N34: 2.1357506 | O34: 1.5325547 | P34: 1.1982409 | S34: CC | T34: 0 | U34: 0 | V34: 0 | W34: 0 | X34: 0 | Y34: 0 | Z34: 0 | AA34: 0 | AB34: 0 | AC34: 0 | AD34: 1 | AE34: 0 | AF34: 0 | AG34: 0 | AH34: 0 | AI34: 1 | AM34: CC | AN34: 0 | AO34: 0 | AP34: 0 | AQ34: 0 | AR34: 0 | AS34: 0 | AT34: 0 | AU34: 0 | AV34: 0 | AW34: 0 | AX34: 0 | AY34: 0 | AZ34: 0 | BA34: 0 | BB34: 0 | BC34: 0
S35: Grand Total | T35: 2 | U35: 6 | V35: 5 | W35: 5 | X35: 7 | Y35: 4 | Z35: 5 | AA35: 6 | AB35: 2 | AC35: 8 | AD35: 2 | AE35: 3 | AF35: 6 | AG35: 9 | AH35: 4 | AI35: 74 | AM35: Grand Total | AN35: 2 | AO35: 6 | AP35: 3 | AQ35: 5 | AR35: 7 | AS35: 1 | AT35: 3 | AU35: 5 | AV35: 2 | AW35: 5 | AX35: 1 | AY35: 3 | AZ35: 5 | BA35: 9 | BB35: 4 | BC35: 61

Sheet T4
C2: =rmsfe_Pivot_T4!B4 -> AG | D2: =rmsfe_Pivot_T4!C4 -> AT | E2: =rmsfe_Pivot_T4!D4 -> AU | F2: =rmsfe_Pivot_T4!E4 -> BR | G2: =rmsfe_Pivot_T4!F4 -> CA | H2: =rmsfe_Pivot_T4!G4 -> CH | I2: =rmsfe_Pivot_T4!H4 -> CN | J2: =rmsfe_Pivot_T4!I4 -> DE | ... Q2: =rmsfe_Pivot_T4!P4 -> US
B3: GDP
B4: =rmsfe_Pivot_T4!A6 -> ZS | C4: =ROUND(rmsfe_Pivot_T4!B6,2)&IF(rmsfe_Pivot_T4!AN6=1,"**",IF(rmsfe_Pivot_T4!T6=1,"*","")) -> 1 | D4: =ROUND(rmsfe_Pivot_T4!C6,2)&IF(rmsfe_Pivot_T4!AO6=1,"**",IF(rmsfe_Pivot_T4!U6=1,"*","")) -> 1 | E4: =ROUND(rmsfe_Pivot_T4!D6,2)&IF(rmsfe_Pivot_T4!AP6=1,"**",IF(rmsfe_Pivot_T4!V6=1,"*","")) -> 1 | F4: =ROUND(rmsfe_Pivot_T4!E6,2)&IF(rmsfe_Pivot_T4!AQ6=1,"**",IF(rmsfe_Pivot_T4!W6=1,"*","")) -> 1 | G4: =ROUND(rmsfe_Pivot_T4!F6,2)&IF(rmsfe_Pivot_T4!AR6=1,"**",IF(rmsfe_Pivot_T4!X6=1,"*","")) -> 1 | H4: =ROUND(rmsfe_Pivot_T4!G6,2)&IF(rmsfe_Pivot_T4!AS6=1,"**",IF(rmsfe_Pivot_T4!Y6=1,"*","")) -> 1 | I4: =ROUND(rmsfe_Pivot_T4!H6,2)&IF(rmsfe_Pivot_T4!AT6=1,"**",IF(rmsfe_Pivot_T4!Z6=1,"*","")) -> 1 | J4: =ROUND(rmsfe_Pivot_T4!I6,2)&IF(rmsfe_Pivot_T4!AU6=1,"**",IF(rmsfe_Pivot_T4!AA6=1,"*","")) -> 1 | ... Q4: =ROUND(rmsfe_Pivot_T4!P6,2)&IF(rmsfe_Pivot_T4!BB6=1,"**",IF(rmsfe_Pivot_T4!AH6=1,"*","")) -> 1
B5: =rmsfe_Pivot_T4!A7 -> ZS\&POOL | C5: =ROUND(rmsfe_Pivot_T4!B7,2)&IF(rmsfe_Pivot_T4!AN7=1,"**",IF(rmsfe_Pivot_T4!T7=1,"*","")) -> 0,99** | D5: =ROUND(rmsfe_Pivot_T4!C7,2)&IF(rmsfe_Pivot_T4!AO7=1,"**",IF(rmsfe_Pivot_T4!U7=1,"*","")) -> 1 | E5: =ROUND(rmsfe_Pivot_T4!D7,2)&IF(rmsfe_Pivot_T4!AP7=1,"**",IF(rmsfe_Pivot_T4!V7=1,"*","")) -> 0,96** | F5: =ROUND(rmsfe_Pivot_T4!E7,2)&IF(rmsfe_Pivot_T4!AQ7=1,"**",IF(rmsfe_Pivot_T4!W7=1,"*","")) -> 0,98 | G5: =ROUND(rmsfe_Pivot_T4!F7,2)&IF(rmsfe_Pivot_T4!AR7=1,"**",IF(rmsfe_Pivot_T4!X7=1,"*","")) -> 0,94** | H5: =ROUND(rmsfe_Pivot_T4!G7,2)&IF(rmsfe_Pivot_T4!AS7=1,"**",IF(rmsfe_Pivot_T4!Y7=1,"*","")) -> 1 | I5: =ROUND(rmsfe_Pivot_T4!H7,2)&IF(rmsfe_Pivot_T4!AT7=1,"**",IF(rmsfe_Pivot_T4!Z7=1,"*","")) -> 1,03 | J5: =ROUND(rmsfe_Pivot_T4!I7,2)&IF(rmsfe_Pivot_T4!AU7=1,"**",IF(rmsfe_Pivot_T4!AA7=1,"*","")) -> 0,97* | ... Q5: =ROUND(rmsfe_Pivot_T4!P7,2)&IF(rmsfe_Pivot_T4!BB7=1,"**",IF(rmsfe_Pivot_T4!AH7=1,"*","")) -> 1 | R5: =rmsfe_Pivot_T4!AI7&"/"&rmsfe_Pivot_T4!BC7 -> 4/3
